Workbook

Sheet Q2. Implied Volatality
B4: CALLS (Implied Volatallity)
B7: Contract Name | C7: Volume | D7: STOCK Price | E7: STRIKE Price | F7: Last Price | G7: Bid | H7: Ask | I7: Risk Free Rate | J7: Dividend Yield | K7: Term (10 Days) | L7: Mid Price | M7: d1 | N7: d2 | O7: Volume | P7: Implied Volatility (Yahoo Finance) | Q7: Implied Volatality (σ) (Calculated) | R7: Call Price (Black-Scholes) | S7: Implied Volatility (Yahoo Finance)
B8: MRK 11/15/24 C95 | C8: 7 | D8: 101.65 | E8: 95 | F8: 6.95 | G8: 6.65 | H8: 6.95 | I8: ='Q1-(Without Zero Volume)'!$J$4 -> 0.046975 | J8: 0.0311 | K8: ='Q1-(Without Zero Volume)'!K4 -> 0.035714286 | L8: =(G8+H8)/2 -> 6.8 | M8: =(LN(D8/E8) + (I8 + (Q8^2) / 2*K8) / (Q8*SQRT(K8))) -> 1.235774 | N8: =M8 - Q8*SQRT(K8) -> -1.0595252 | O8: 7 | P8: 26.781515 | Q8: 12.145582 | R8: =E8*_xlfn.NORM.S.DIST(N8,TRUE) - F8*EXP(-J8*L8)*_xlfn.NORM.S.DIST(O8,TRUE) -> 8.1194025 | S8: =P8-Q8 -> 14.635934
B9: MRK 11/15/24 C98 | C9: 3 | D9: 101.65 | E9: 98 | F9: 4.2 | G9: 4.15 | H9: 4.3 | I9: ='Q1-(Without Zero Volume)'!$J$4 -> 0.046975 | J9: 0.0311 | K9: =K8 -> 0.035714286 | L9: =(G9+H9)/2 -> 4.225 | M9: =(LN(D9/E9) + (I9 + (Q9^2) / 2*K9) / (Q9*SQRT(K9))) -> 1.4325073 | N9: =M9 - Q9*SQRT(K9) -> -1.3253044 | O9: 3 | P9: 26.573425 | Q9: 14.592968 | R9: =E9*_xlfn.NORM.S.DIST(N9,TRUE) - F9*EXP(-J9*L9)*_xlfn.NORM.S.DIST(O9,TRUE) -> 5.390562 | S9: =P9-Q9 -> 11.980457
B10: MRK 11/15/24 C99 | C10: 7 | D10: 101.65 | E10: 99 | F10: 3.25 | G10: 3.4 | H10: 3.55 | I10: ='Q1-(Without Zero Volume)'!$J$4 -> 0.046975 | J10: 0.0311 | K10: =K9 -> 0.035714286 | L10: =(G10+H10)/2 -> 3.475 | M10: =(LN(D10/E10) + (I10 + (Q10^2) / 2*K10) / (Q10*SQRT(K10))) -> 1.5213034 | N10: =M10 - Q10*SQRT(K10) -> -1.4367109 | O10: 7 | P10: 26.641626 | Q10: 15.65234 | R10: =E10*_xlfn.NORM.S.DIST(N10,TRUE) - F10*EXP(-J10*L10)*_xlfn.NORM.S.DIST(O10,TRUE) -> 4.5475299 | S10: =P10-Q10 -> 10.989286
B11: MRK 11/15/24 C100 | C11: 8 | D11: 101.65 | E11: 100 | F11: 2.35 | G11: 2.73 | H11: 2.84 | I11: ='Q1-(Without Zero Volume)'!$J$4 -> 0.046975 | J11: 0.0311 | K11: =K10 -> 0.035714286 | L11: =(G11+H11)/2 -> 2.785 | M11: =(LN(D11/E11) + (I11 + (Q11^2) / 2*K11) / (Q11*SQRT(K11))) -> 1.6258619 | N11: =M11 - Q11*SQRT(K11) -> -1.5636755 | O11: 8 | P11: 25.299459 | Q11: 16.877446 | R11: =E11*_xlfn.NORM.S.DIST(N11,TRUE) - F11*EXP(-J11*L11)*_xlfn.NORM.S.DIST(O11,TRUE) -> 3.7396653 | S11: =P11-Q11 -> 8.4220136
B12: MRK 11/15/24 C101 | C12: 16 | D12: 101.65 | E12: 101 | F12: 1.87 | G12: 2.11 | H12: 2.21 | I12: ='Q1-(Without Zero Volume)'!$J$4 -> 0.046975 | J12: 0.0311 | K12: =K11 -> 0.035714286 | L12: =(G12+H12)/2 -> 2.16 | M12: =(LN(D12/E12) + (I12 + (Q12^2) / 2*K12) / (Q12*SQRT(K12))) -> 1.7141561 | N12: =M12 - Q12*SQRT(K12) -> -1.6735937 | O12: 16 | P12: 25.354883 | Q12: 17.926287 | R12: =E12*_xlfn.NORM.S.DIST(N12,TRUE) - F12*EXP(-J12*L12)*_xlfn.NORM.S.DIST(O12,TRUE) -> 3.0091214 | S12: =P12-Q12 -> 7.4285962
B13: MRK 11/15/24 C102 | C13: 41 | D13: 101.65 | E13: 102 | F13: 1.69 | G13: 1.6 | H13: 1.66 | I13: ='Q1-(Without Zero Volume)'!$J$4 -> 0.046975 | J13: 0.0311 | K13: =K12 -> 0.035714286 | L13: =(G13+H13)/2 -> 1.63 | M13: =(LN(D13/E13) + (I13 + (Q13^2) / 2*K13) / (Q13*SQRT(K13))) -> 1.7791679 | N13: =M13 - Q13*SQRT(K13) -> -1.7594928 | O13: 41 | P13: 24.818048 | Q13: 18.724832 | R13: =E13*_xlfn.NORM.S.DIST(N13,TRUE) - F13*EXP(-J13*L13)*_xlfn.NORM.S.DIST(O13,TRUE) -> 2.3967217 | S13: =P13-Q13 -> 6.0932162
B14: MRK 11/15/24 C103 | C14: 19 | D14: 101.65 | E14: 103 | F14: 1.27 | G14: 1.17 | H14: 1.22 | I14: ='Q1-(Without Zero Volume)'!$J$4 -> 0.046975 | J14: 0.0311 | K14: =K13 -> 0.035714286 | L14: =(G14+H14)/2 -> 1.195 | M14: =(LN(D14/E14) + (I14 + (Q14^2) / 2*K14) / (Q14*SQRT(K14))) -> 1.8825727 | N14: =M14 - Q14*SQRT(K14) -> -1.8840166 | O14: 19 | P14: 24.502392 | Q14: 19.930917 | R14: =E14*_xlfn.NORM.S.DIST(N14,TRUE) - F14*EXP(-J14*L14)*_xlfn.NORM.S.DIST(O14,TRUE) -> 1.8438132 | S14: =P14-Q14 -> 4.5714747
B15: MRK 11/15/24 C104 | C15: 2 | D15: 101.65 | E15: 104 | F15: 0.87 | G15: 0.82 | H15: 0.87 | I15: ='Q1-(Without Zero Volume)'!$J$4 -> 0.046975 | J15: 0.0311 | K15: =K14 -> 0.035714286 | L15: =(G15+H15)/2 -> 0.845 | M15: =(LN(D15/E15) + (I15 + (Q15^2) / 2*K15) / (Q15*SQRT(K15))) -> 2.0098107 | N15: =M15 - Q15*SQRT(K15) -> -2.0322785 | O15: 2 | P15: 24.700979 | Q15: 21.388726 | R15: =E15*_xlfn.NORM.S.DIST(N15,TRUE) - F15*EXP(-J15*L15)*_xlfn.NORM.S.DIST(O15,TRUE) -> 1.3623689 | S15: =P15-Q15 -> 3.3122532
B16: MRK 11/15/24 C105 | C16: 475 | D16: 101.65 | E16: 105 | F16: 0.52 | G16: 0.57 | H16: 0.61 | I16: ='Q1-(Without Zero Volume)'!$J$4 -> 0.046975 | J16: 0.0311 | K16: =K15 -> 0.035714286 | L16: =(G16+H16)/2 -> 0.59 | M16: =(LN(D16/E16) + (I16 + (Q16^2) / 2*K16) / (Q16*SQRT(K16))) -> 2.1475661 | N16: =M16 - Q16*SQRT(K16) -> -2.1907599 | O16: 475 | P16: 24.196188 | Q16: 22.956263 | R16: =E16*_xlfn.NORM.S.DIST(N16,TRUE) - F16*EXP(-J16*L16)*_xlfn.NORM.S.DIST(O16,TRUE) -> 0.98408598 | S16: =P16-Q16 -> 1.2399245
B17: MRK 11/15/24 C106 | C17: 29 | D17: 101.65 | E17: 106 | F17: 0.35 | G17: 0.39 | H17: 0.42 | I17: ='Q1-(Without Zero Volume)'!$J$4 -> 0.046975 | J17: 0.0311 | K17: =K16 -> 0.035714286 | L17: =(G17+H17)/2 -> 0.405 | M17: =(LN(D17/E17) + (I17 + (Q17^2) / 2*K17) / (Q17*SQRT(K17))) -> 2.264931 | N17: =M17 - Q17*SQRT(K17) -> -2.3282841 | O17: 29 | P17: 24.819933 | Q17: 24.30501 | R17: =E17*_xlfn.NORM.S.DIST(N17,TRUE) - F17*EXP(-J17*L17)*_xlfn.NORM.S.DIST(O17,TRUE) -> 0.70892308 | S17: =P17-Q17 -> 0.51492309
B18: MRK 11/15/24 C107 | C18: 2 | D18: 101.65 | E18: 107 | F18: 0.37 | G18: 0.24 | H18: 0.29 | I18: ='Q1-(Without Zero Volume)'!$J$4 -> 0.046975 | J18: 0.0311 | K18: =K17 -> 0.035714286 | L18: =(G18+H18)/2 -> 0.265 | M18: =(LN(D18/E18) + (I18 + (Q18^2) / 2*K18) / (Q18*SQRT(K18))) -> 2.3117288 | N18: =M18 - Q18*SQRT(K18) -> -2.3943519 | O18: 2 | P18: 24.942793 | Q18: 24.902238 | R18: =E18*_xlfn.NORM.S.DIST(N18,TRUE) - F18*EXP(-J18*L18)*_xlfn.NORM.S.DIST(O18,TRUE) -> 0.53214787 | S18: =P18-Q18 -> 0.040554768
B19: MRK 11/15/24 C110 | C19: 22 | D19: 101.65 | E19: 110 | F19: 0.08 | G19: 0.09 | H19: 0.12 | I19: ='Q1-(Without Zero Volume)'!$J$4 -> 0.046975 | J19: 0.0311 | K19: =K18 -> 0.035714286 | L19: =(G19+H19)/2 -> 0.105 | M19: =(LN(D19/E19) + (I19 + (Q19^2) / 2*K19) / (Q19*SQRT(K19))) -> 2.6448595 | N19: =M19 - Q19*SQRT(K19) -> -2.7854481 | O19: 22 | P19: 28.406557 | Q19: 28.734487 | R19: =E19*_xlfn.NORM.S.DIST(N19,TRUE) - F19*EXP(-J19*L19)*_xlfn.NORM.S.DIST(O19,TRUE) -> 0.21425672 | S19: =P19-Q19 -> -0.32792946
B20: MRK 11/15/24 C114 | C20: 68 | D20: 101.65 | E20: 114 | F20: 0.03 | G20: 0.02 | H20: 0.12 | I20: ='Q1-(Without Zero Volume)'!$J$4 -> 0.046975 | J20: 0.0311 | K20: =K19 -> 0.035714286 | L20: =(G20+H20)/2 -> 0.07 | M20: =(LN(D20/E20) + (I20 + (Q20^2) / 2*K20) / (Q20*SQRT(K20))) -> 2.7597516 | N20: =M20 - Q20*SQRT(K20) -> -2.9726883 | O20: 68 | P20: 32.74509 | Q20: 30.333221 | R20: =E20*_xlfn.NORM.S.DIST(N20,TRUE) - F20*EXP(-J20*L20)*_xlfn.NORM.S.DIST(O20,TRUE) -> 0.13833158 | S20: =P20-Q20 -> 2.4118697
B21: MRK 11/15/24 C130 | C21: 7 | D21: 101.65 | E21: 130 | F21: 0.01 | G21: 0 | H21: 0.04 | I21: ='Q1-(Without Zero Volume)'!$J$4 -> 0.046975 | J21: 0.0311 | K21: =K20 -> 0.035714286 | L21: =(G21+H21)/2 -> 0.02 | M21: =(LN(D21/E21) + (I21 + (Q21^2) / 2*K21) / (Q21*SQRT(K21))) -> 2.8538442 | N21: =M21 - Q21*SQRT(K21) -> -3.3306508 | O21: 7 | P21: 88.830597 | Q21: 32.725271 | R21: =E21*_xlfn.NORM.S.DIST(N21,TRUE) - F21*EXP(-J21*L21)*_xlfn.NORM.S.DIST(O21,TRUE) -> 0.046324312 | S21: =P21-Q21 -> 56.105326
B25: PUT (Implied Volatallity)
B28: Contract Name | D28: Last Trade Date (EDT) | E28: SPOT Price | F28: STRIKE Price | G28: Last Price | H28: Bid | I28: Ask | J28: Risk Free Rate | K28: Dividend Yield | L28: Term (10 Days) | M28: Mid Price | N28: d1 | O28: d2 | Q28: Implied Volatality (σ) (Calculated) | R28: Call Price (Black-Scholes) | S28: Implied Volatility
B29: ='[1]Tracked Data - MRK'!S9 -> MRK241115P00060000 | D29: ='[1]Tracked Data - MRK'!T9 -> 45589.762 | E29: 101.65 | F29: ='[1]Tracked Data - MRK'!U9 -> 60 | G29: ='[1]Tracked Data - MRK'!V9 -> 0.02 | H29: ='[1]Tracked Data - MRK'!W9 -> 0 | I29: ='[1]Tracked Data - MRK'!X9 -> 0.28 | J29: =J10 -> 0.0311 | K29: =K10 -> 0.035714286 | L29: =10/365 -> 0.02739726 | M29: =(H29+I29)/2 -> 0.14 | N29: =(LN(E29/F29) + (J29+ (Q29^2) / 2*L29) / (Q29*SQRT(L29))) -> 0.82436989 | O29: =N29-Q29*SQRT(L29) -> 0.36558868 | Q29: 2.7717372 | R29: =F29*EXP(-J29*L29)*_xlfn.NORM.S.DIST(-O29,TRUE)-E29*_xlfn.NORM.S.DIST(-N29,TRUE) -> 0.59740256 | S29: 1.4609402
B30: ='[1]Tracked Data - MRK'!S10 -> MRK241115P00070000 | D30: ='[1]Tracked Data - MRK'!T10 -> 45595.751 | E30: 101.65 | F30: ='[1]Tracked Data - MRK'!U10 -> 70 | G30: ='[1]Tracked Data - MRK'!V10 -> 0.03 | H30: ='[1]Tracked Data - MRK'!W10 -> 0 | I30: ='[1]Tracked Data - MRK'!X10 -> 0.29 | J30: =J11 -> 0.0311 | K30: =K29 -> 0.035714286 | L30: =L29 -> 0.02739726 | M30: =(H30+I30)/2 -> 0.145 | N30: =(LN(E30/F30) + (J30+ (Q30^2) / 2*L30) / (Q30*SQRT(L30))) -> 0.63941239 | O30: =N30-Q30*SQRT(L30) -> 0.27947698 | Q30: 2.1745581 | R30: =F30*EXP(-J30*L30)*_xlfn.NORM.S.DIST(-O30,TRUE)-E30*_xlfn.NORM.S.DIST(-N30,TRUE) -> 0.71366836 | S30: 1.0820358
B31: ='[1]Tracked Data - MRK'!S11 -> MRK241115P00080000 | D31: ='[1]Tracked Data - MRK'!T11 -> 45593.663 | E31: 101.65 | F31: ='[1]Tracked Data - MRK'!U11 -> 80 | G31: ='[1]Tracked Data - MRK'!V11 -> 0.09 | H31: ='[1]Tracked Data - MRK'!W11 -> 0 | I31: ='[1]Tracked Data - MRK'!X11 -> 0.13 | J31: =J12 -> 0.0311 | K31: =K30 -> 0.035714286 | L31: =L30 -> 0.02739726 | M31: =(H31+I31)/2 -> 0.065 | N31: =(LN(E31/F31) + (J31+ (Q31^2) / 2*L31) / (Q31*SQRT(L31))) -> 0.48892477 | O31: =N31-Q31*SQRT(L31) -> 0.23663289 | Q31: 1.5242272 | R31: =F31*EXP(-J31*L31)*_xlfn.NORM.S.DIST(-O31,TRUE)-E31*_xlfn.NORM.S.DIST(-N31,TRUE) -> 0.72968263 | S31: 0.64844102
B32: ='[1]Tracked Data - MRK'!S12 -> MRK241115P00085000 | D32: ='[1]Tracked Data - MRK'!T12 -> 45596.712 | E32: 101.65 | F32: ='[1]Tracked Data - MRK'!U12 -> 85 | G32: ='[1]Tracked Data - MRK'!V12 -> 0.06 | H32: ='[1]Tracked Data - MRK'!W12 -> 0 | I32: ='[1]Tracked Data - MRK'!X12 -> 0.1 | J32: =J13 -> 0.0311 | K32: =K31 -> 0.035714286 | L32: =L31 -> 0.02739726 | M32: =(H32+I32)/2 -> 0.05 | N32: =(LN(E32/F32) + (J32+ (Q32^2) / 2*L32) / (Q32*SQRT(L32))) -> 0.43532008 | O32: =N32-Q32*SQRT(L32) -> 0.23854429 | Q32: 1.1888255 | R32: =F32*EXP(-J32*L32)*_xlfn.NORM.S.DIST(-O32,TRUE)-E32*_xlfn.NORM.S.DIST(-N32,TRUE) -> 0.74388086 | S32: 0.537114
B33: ='[1]Tracked Data - MRK'!S13 -> MRK241115P00090000 | D33: ='[1]Tracked Data - MRK'!T13 -> 45601.605 | E33: 101.65 | F33: ='[1]Tracked Data - MRK'!U13 -> 90 | G33: ='[1]Tracked Data - MRK'!V13 -> 0.39 | H33: ='[1]Tracked Data - MRK'!W13 -> 0.01 | I33: ='[1]Tracked Data - MRK'!X13 -> 0.09 | J33: =J14 -> 0.0311 | K33: =K32 -> 0.035714286 | L33: =L32 -> 0.02739726 | M33: =(H33+I33)/2 -> 0.05 | N33: =(LN(E33/F33) + (J33+ (Q33^2) / 2*L33) / (Q33*SQRT(L33))) -> 0.41378718 | O33: =N33-Q33*SQRT(L33) -> 0.27371208 | Q33: 0.84626692 | R33: =F33*EXP(-J33*L33)*_xlfn.NORM.S.DIST(-O33,TRUE)-E33*_xlfn.NORM.S.DIST(-N33,TRUE) -> 0.7520073 | S33: 0.43945873
B34: ='[1]Tracked Data - MRK'!S14 -> MRK241115P00095000 | D34: ='[1]Tracked Data - MRK'!T14 -> 45601.646 | E34: 101.65 | F34: ='[1]Tracked Data - MRK'!U14 -> 95 | G34: ='[1]Tracked Data - MRK'!V14 -> 0.32 | H34: ='[1]Tracked Data - MRK'!W14 -> 0 | I34: ='[1]Tracked Data - MRK'!X14 -> 0.33 | J34: =J15 -> 0.0311 | K34: =K33 -> 0.035714286 | L34: =L33 -> 0.02739726 | M34: =(H34+I34)/2 -> 0.165 | N34: =(LN(E34/F34) + (J34+ (Q34^2) / 2*L34) / (Q34*SQRT(L34))) -> 0.47702658 | O34: =N34-Q34*SQRT(L34) -> 0.39228474 | Q34: 0.51196974 | R34: =F34*EXP(-J34*L34)*_xlfn.NORM.S.DIST(-O34,TRUE)-E34*_xlfn.NORM.S.DIST(-N34,TRUE) -> 0.78749392 | S34: 0.31934274
B35: ='[1]Tracked Data - MRK'!S15 -> MRK241115P00098000 | D35: ='[1]Tracked Data - MRK'!T15 -> 45601.634 | E35: 101.65 | F35: ='[1]Tracked Data - MRK'!U15 -> 98 | G35: ='[1]Tracked Data - MRK'!V15 -> 0.81 | H35: ='[1]Tracked Data - MRK'!W15 -> 0.08 | I35: ='[1]Tracked Data - MRK'!X15 -> 0.26 | J35: =J16 -> 0.0311 | K35: =K34 -> 0.035714286 | L35: =L34 -> 0.02739726 | M35: =(H35+I35)/2 -> 0.17 | N35: =(LN(E35/F35) + (J35+ (Q35^2) / 2*L35) / (Q35*SQRT(L35))) -> 0.69833411 | O35: =N35-Q35*SQRT(L35) -> 0.64953976 | Q35: 0.29479219 | R35: =F35*EXP(-J35*L35)*_xlfn.NORM.S.DIST(-O35,TRUE)-E35*_xlfn.NORM.S.DIST(-N35,TRUE) -> 0.61344206 | S35: 0.29785858
B36: ='[1]Tracked Data - MRK'!S16 -> MRK241115P00099000 | D36: ='[1]Tracked Data - MRK'!T16 -> 45600.78 | E36: 101.65 | F36: ='[1]Tracked Data - MRK'!U16 -> 99 | G36: ='[1]Tracked Data - MRK'!V16 -> 1.08 | H36: ='[1]Tracked Data - MRK'!W16 -> 0.98 | I36: ='[1]Tracked Data - MRK'!X16 -> 1.08 | J36: =J17 -> 0.0311 | K36: =K35 -> 0.035714286 | L36: =L35 -> 0.02739726 | M36: =(H36+I36)/2 -> 1.03 | N36: =(LN(E36/F36) + (J36+ (Q36^2) / 2*L36) / (Q36*SQRT(L36))) -> 0.59013834 | O36: =N36-Q36*SQRT(L36) -> 0.53196809 | Q36: 0.35143692 | R36: =F36*EXP(-J36*L36)*_xlfn.NORM.S.DIST(-O36,TRUE)-E36*_xlfn.NORM.S.DIST(-N36,TRUE) -> 1.2021059 | S36: 0.29248754
B37: ='[1]Tracked Data - MRK'!S17 -> MRK241115P00100000 | D37: ='[1]Tracked Data - MRK'!T17 -> 45601.64 | E37: 101.65 | F37: ='[1]Tracked Data - MRK'!U17 -> 100 | G37: ='[1]Tracked Data - MRK'!V17 -> 1.46 | H37: ='[1]Tracked Data - MRK'!W17 -> 1.38 | I37: ='[1]Tracked Data - MRK'!X17 -> 1.44 | J37: =J18 -> 0.0311 | K37: =K36 -> 0.035714286 | L37: =L36 -> 0.02739726 | M37: =(H37+I37)/2 -> 1.41 | N37: =(LN(E37/F37) + (J37+ (Q37^2) / 2*L37) / (Q37*SQRT(L37))) -> 0.60629816 | O37: =N37-Q37*SQRT(L37) -> 0.55098739 | Q37: 0.33416132 | R37: =F37*EXP(-J37*L37)*_xlfn.NORM.S.DIST(-O37,TRUE)-E37*_xlfn.NORM.S.DIST(-N37,TRUE) -> 1.3924468 | S37: 0.29102271
B38: ='[1]Tracked Data - MRK'!S18 -> MRK241115P00101000 | D38: ='[1]Tracked Data - MRK'!T18 -> 45601.644 | E38: 101.65 | F38: ='[1]Tracked Data - MRK'!U18 -> 101 | G38: ='[1]Tracked Data - MRK'!V18 -> 1.82 | H38: ='[1]Tracked Data - MRK'!W18 -> 1.74 | I38: ='[1]Tracked Data - MRK'!X18 -> 1.88 | J38: =J19 -> 0.0311 | K38: =K37 -> 0.035714286 | L38: =L37 -> 0.02739726 | M38: =(H38+I38)/2 -> 1.81 | N38: =(LN(E38/F38) + (J38+ (Q38^2) / 2*L38) / (Q38*SQRT(L38))) -> 0.62202071 | O38: =N38-Q38*SQRT(L38) -> 0.56923858 | Q38: 0.31888442 | R38: =F38*EXP(-J38*L38)*_xlfn.NORM.S.DIST(-O38,TRUE)-E38*_xlfn.NORM.S.DIST(-N38,TRUE) -> 1.5829245 | S38: 0.29004616
B39: ='[1]Tracked Data - MRK'!S19 -> MRK241115P00102000 | D39: ='[1]Tracked Data - MRK'!T19 -> 45601.643 | E39: 101.65 | F39: ='[1]Tracked Data - MRK'!U19 -> 102 | G39: ='[1]Tracked Data - MRK'!V19 -> 2.39 | H39: ='[1]Tracked Data - MRK'!W19 -> 2.3 | I39: ='[1]Tracked Data - MRK'!X19 -> 2.41 | J39: =J20 -> 0.0311 | K39: =K38 -> 0.035714286 | L39: =L38 -> 0.02739726 | M39: =(H39+I39)/2 -> 2.355 | N39: =(LN(E39/F39) + (J39+ (Q39^2) / 2*L39) / (Q39*SQRT(L39))) -> 0.60170566 | O39: =N39-Q39*SQRT(L39) -> 0.54792284 | Q39: 0.32493017 | R39: =F39*EXP(-J39*L39)*_xlfn.NORM.S.DIST(-O39,TRUE)-E39*_xlfn.NORM.S.DIST(-N39,TRUE) -> 1.9255492 | S39: 0.29077858
B40: ='[1]Tracked Data - MRK'!S20 -> MRK241115P00103000 | D40: ='[1]Tracked Data - MRK'!T20 -> 45600.866 | E40: 101.65 | F40: ='[1]Tracked Data - MRK'!U20 -> 103 | G40: ='[1]Tracked Data - MRK'!V20 -> 3.3 | H40: ='[1]Tracked Data - MRK'!W20 -> 2.79 | I40: ='[1]Tracked Data - MRK'!X20 -> 3.1 | J40: =J21 -> 0.0311 | K40: =K39 -> 0.035714286 | L40: =L39 -> 0.02739726 | M40: =(H40+I40)/2 -> 2.945 | N40: =(LN(E40/F40) + (J40+ (Q40^2) / 2*L40) / (Q40*SQRT(L40))) -> 0.57426495 | O40: =N40-Q40*SQRT(L40) -> 0.51869693 | Q40: 0.3357155 | R40: =F40*EXP(-J40*L40)*_xlfn.NORM.S.DIST(-O40,TRUE)-E40*_xlfn.NORM.S.DIST(-N40,TRUE) -> 2.3218702 | S40: 0.30396204
B41: ='[1]Tracked Data - MRK'!S21 -> MRK241115P00104000 | D41: ='[1]Tracked Data - MRK'!T21 -> 45601.646 | E41: 101.65 | F41: ='[1]Tracked Data - MRK'!U21 -> 104 | G41: ='[1]Tracked Data - MRK'!V21 -> 3.7 | H41: ='[1]Tracked Data - MRK'!W21 -> 3.65 | I41: ='[1]Tracked Data - MRK'!X21 -> 3.75 | J41: =#REF! -> #REF! | K41: =K40 -> 0.035714286 | L41: =L40 -> 0.02739726 | M41: =(H41+I41)/2 -> 3.7 | N41: =(LN(E41/F41) + (J41+ (Q41^2) / 2*L41) / (Q41*SQRT(L41))) -> #REF! | O41: =N41-Q41*SQRT(L41) -> #REF! | Q41: 0.36887944 | R41: =F41*EXP(-J41*L41)*_xlfn.NORM.S.DIST(-O41,TRUE)-E41*_xlfn.NORM.S.DIST(-N41,TRUE) -> #REF! | S41: 0.30127652
B42: ='[1]Tracked Data - MRK'!S22 -> MRK241115P00105000 | D42: ='[1]Tracked Data - MRK'!T22 -> 45601.622 | E42: 101.65 | F42: ='[1]Tracked Data - MRK'!U22 -> 105 | G42: ='[1]Tracked Data - MRK'!V22 -> 4.57 | H42: ='[1]Tracked Data - MRK'!W22 -> 4.45 | I42: ='[1]Tracked Data - MRK'!X22 -> 4.6 | J42: =#REF! -> #REF! | K42: =K41 -> 0.035714286 | L42: =L41 -> 0.02739726 | M42: =(H42+I42)/2 -> 4.525 | N42: =(LN(E42/F42) + (J42+ (Q42^2) / 2*L42) / (Q42*SQRT(L42))) -> #REF! | O42: =N42-Q42*SQRT(L42) -> #REF! | Q42: 0.41238558 | R42: =F42*EXP(-J42*L42)*_xlfn.NORM.S.DIST(-O42,TRUE)-E42*_xlfn.NORM.S.DIST(-N42,TRUE) -> #REF! | S42: 0.32178413
B43: ='[1]Tracked Data - MRK'!S23 -> MRK241115P00106000 | D43: ='[1]Tracked Data - MRK'!T23 -> 45600.763 | E43: 101.65 | F43: ='[1]Tracked Data - MRK'!U23 -> 106 | G43: ='[1]Tracked Data - MRK'!V23 -> 5.1 | H43: ='[1]Tracked Data - MRK'!W23 -> 5 | I43: ='[1]Tracked Data - MRK'!X23 -> 5.4 | J43: =#REF! -> #REF! | K43: =K42 -> 0.035714286 | L43: =L42 -> 0.02739726 | M43: =(H43+I43)/2 -> 5.2 | N43: =(LN(E43/F43) + (J43+ (Q43^2) / 2*L43) / (Q43*SQRT(L43))) -> #REF! | O43: =N43-Q43*SQRT(L43) -> #REF! | Q43: 0.43108975 | R43: =F43*EXP(-J43*L43)*_xlfn.NORM.S.DIST(-O43,TRUE)-E43*_xlfn.NORM.S.DIST(-N43,TRUE) -> #REF! | S43: 0.32691103
B44: ='[1]Tracked Data - MRK'!S24 -> MRK241115P00107000 | D44: ='[1]Tracked Data - MRK'!T24 -> 45600.724 | E44: 101.65 | F44: ='[1]Tracked Data - MRK'!U24 -> 107 | G44: ='[1]Tracked Data - MRK'!V24 -> 6 | H44: ='[1]Tracked Data - MRK'!W24 -> 5.75 | I44: ='[1]Tracked Data - MRK'!X24 -> 6.4 | J44: =#REF! -> #REF! | K44: =K43 -> 0.035714286 | L44: =L43 -> 0.02739726 | M44: =(H44+I44)/2 -> 6.075 | N44: =(LN(E44/F44) + (J44+ (Q44^2) / 2*L44) / (Q44*SQRT(L44))) -> #REF! | O44: =N44-Q44*SQRT(L44) -> #REF! | Q44: 0.47914753 | R44: =F44*EXP(-J44*L44)*_xlfn.NORM.S.DIST(-O44,TRUE)-E44*_xlfn.NORM.S.DIST(-N44,TRUE) -> #REF! | S44: 0.36524072
B45: ='[1]Tracked Data - MRK'!S25 -> MRK241115P00108000 | D45: ='[1]Tracked Data - MRK'!T25 -> 45597.687 | E45: 101.65 | F45: ='[1]Tracked Data - MRK'!U25 -> 108 | G45: ='[1]Tracked Data - MRK'!V25 -> 5.85 | H45: ='[1]Tracked Data - MRK'!W25 -> 7.05 | I45: ='[1]Tracked Data - MRK'!X25 -> 7.35 | J45: =#REF! -> #REF! | K45: =K44 -> 0.035714286 | L45: =L44 -> 0.02739726 | M45: =(H45+I45)/2 -> 7.2 | N45: =(LN(E45/F45) + (J45+ (Q45^2) / 2*L45) / (Q45*SQRT(L45))) -> #REF! | O45: =N45-Q45*SQRT(L45) -> #REF! | Q45: 0.56056945 | R45: =F45*EXP(-J45*L45)*_xlfn.NORM.S.DIST(-O45,TRUE)-E45*_xlfn.NORM.S.DIST(-N45,TRUE) -> #REF! | S45: 0.39111937
B46: ='[1]Tracked Data - MRK'!S26 -> MRK241115P00109000 | D46: ='[1]Tracked Data - MRK'!T26 -> 45600.612 | E46: 101.65 | F46: ='[1]Tracked Data - MRK'!U26 -> 109 | G46: ='[1]Tracked Data - MRK'!V26 -> 7.25 | H46: ='[1]Tracked Data - MRK'!W26 -> 7.95 | I46: ='[1]Tracked Data - MRK'!X26 -> 8.35 | J46: =#REF! -> #REF! | K46: =K45 -> 0.035714286 | L46: =L45 -> 0.02739726 | M46: =(H46+I46)/2 -> 8.15 | N46: =(LN(E46/F46) + (J46+ (Q46^2) / 2*L46) / (Q46*SQRT(L46))) -> #REF! | O46: =N46-Q46*SQRT(L46) -> #REF! | Q46: 0.61581756 | R46: =F46*EXP(-J46*L46)*_xlfn.NORM.S.DIST(-O46,TRUE)-E46*_xlfn.NORM.S.DIST(-N46,TRUE) -> #REF! | S46: 0.42578699
B47: ='[1]Tracked Data - MRK'!S27 -> MRK241115P00110000 | D47: ='[1]Tracked Data - MRK'!T27 -> 45601.622 | E47: 101.65 | F47: ='[1]Tracked Data - MRK'!U27 -> 110 | G47: ='[1]Tracked Data - MRK'!V27 -> 9.2 | H47: ='[1]Tracked Data - MRK'!W27 -> 9.05 | I47: ='[1]Tracked Data - MRK'!X27 -> 9.3 | J47: =#REF! -> #REF! | K47: =K46 -> 0.035714286 | L47: =L46 -> 0.02739726 | M47: =(H47+I47)/2 -> 9.175 | N47: =(LN(E47/F47) + (J47+ (Q47^2) / 2*L47) / (Q47*SQRT(L47))) -> #REF! | O47: =N47-Q47*SQRT(L47) -> #REF! | Q47: 0.68117607 | R47: =F47*EXP(-J47*L47)*_xlfn.NORM.S.DIST(-O47,TRUE)-E47*_xlfn.NORM.S.DIST(-N47,TRUE) -> #REF! | S47: 0.44775943
B48: ='[1]Tracked Data - MRK'!S28 -> MRK241115P00111000 | D48: ='[1]Tracked Data - MRK'!T28 -> 45597.736 | E48: 101.65 | F48: ='[1]Tracked Data - MRK'!U28 -> 111 | G48: ='[1]Tracked Data - MRK'!V28 -> 9 | H48: ='[1]Tracked Data - MRK'!W28 -> 10.05 | I48: ='[1]Tracked Data - MRK'!X28 -> 10.3 | J48: =#REF! -> #REF! | K48: =K47 -> 0.035714286 | L48: =L47 -> 0.02739726 | M48: =(H48+I48)/2 -> 10.175 | N48: =(LN(E48/F48) + (J48+ (Q48^2) / 2*L48) / (Q48*SQRT(L48))) -> #REF! | O48: =N48-Q48*SQRT(L48) -> #REF! | Q48: 0.74076021 | R48: =F48*EXP(-J48*L48)*_xlfn.NORM.S.DIST(-O48,TRUE)-E48*_xlfn.NORM.S.DIST(-N48,TRUE) -> #REF! | S48: 0.47998567
B49: ='[1]Tracked Data - MRK'!S29 -> MRK241115P00112000 | D49: ='[1]Tracked Data - MRK'!T29 -> 45587.784 | E49: 101.65 | F49: ='[1]Tracked Data - MRK'!U29 -> 112 | G49: ='[1]Tracked Data - MRK'!V29 -> 6.54 | H49: ='[1]Tracked Data - MRK'!W29 -> 11.05 | I49: ='[1]Tracked Data - MRK'!X29 -> 12.75 | J49: =#REF! -> #REF! | K49: =K48 -> 0.035714286 | L49: =L48 -> 0.02739726 | M49: =(H49+I49)/2 -> 11.9 | N49: =(LN(E49/F49) + (J49+ (Q49^2) / 2*L49) / (Q49*SQRT(L49))) -> #REF! | O49: =N49-Q49*SQRT(L49) -> #REF! | Q49: 0.90186219 | R49: =F49*EXP(-J49*L49)*_xlfn.NORM.S.DIST(-O49,TRUE)-E49*_xlfn.NORM.S.DIST(-N49,TRUE) -> #REF! | S49: 0.64599963
B50: ='[1]Tracked Data - MRK'!S30 -> MRK241115P00113000 | D50: ='[1]Tracked Data - MRK'!T30 -> 45596.567 | E50: 101.65 | F50: ='[1]Tracked Data - MRK'!U30 -> 113 | G50: ='[1]Tracked Data - MRK'!V30 -> 14.05 | H50: ='[1]Tracked Data - MRK'!W30 -> 12 | I50: ='[1]Tracked Data - MRK'!X30 -> 12.8 | J50: =#REF! -> #REF! | K50: =K49 -> 0.035714286 | L50: =L49 -> 0.02739726 | M50: =(H50+I50)/2 -> 12.4 | N50: =(LN(E50/F50) + (J50+ (Q50^2) / 2*L50) / (Q50*SQRT(L50))) -> #REF! | O50: =N50-Q50*SQRT(L50) -> #REF! | Q50: 0.88729413 | R50: =F50*EXP(-J50*L50)*_xlfn.NORM.S.DIST(-O50,TRUE)-E50*_xlfn.NORM.S.DIST(-N50,TRUE) -> #REF! | S50: 0.56738714
...

Sheet Q1-(Without Zero Volume)
A1: A. PUT-CALL Parity for all Options as on November 5, 2024
V2: Arbitrage Strategy
A3: Option Symbol | B3: Option Date | C3: Trading Volume | D3: Call Price( Bid and ask Average) ( C ) | E3: Option Symbol | F3: Trading Volume | G3: Put Price (P) ( Bid and ask Average)\ | H3: Stock Price/ Spot Price (S) | I3: Strike Price (K) | J3: Risk-Free Rate ( R ) | K3: (t)=Time to Maturity (15-6=9/252) | L3: S+P | M3: e^(-r*t) | N3: K*e^(-rt) | O3: C+K*e^-rt | P3: Violation of Put-Call parity | Q3: Difference | R3: C-P | S3: ='Q1. Put- Call Parity(With zero '!K4 -> S - K*e^-r(T-t) | T3: Difference | U3: Theoretical Value of Put Option P=C+K*e^-rt-S | V3: S+P>C+K⋅e ^−r(T−t) (OVERVALUED) | W3: S+P<C+K⋅e ^−r(T−t) (UNDERVALUED)
A4: MRK 11/15/24 C95 | B4: 45423 | C4: 12 | D4: =('Bloomberg Raw Data-5th(No zero)'!C6+'Bloomberg Raw Data-5th(No zero)'!D6)/2 -> 6.8000002 | E4: MRK 11/15/24 P95 | F4: 24 | G4: =('Bloomberg Raw Data-5th(No zero)'!J6+'Bloomberg Raw Data-5th(No zero)'!K6)/2 -> 0.16999999 | H4: 101.65 | I4: 95 | J4: =4.6975/100 -> 0.046975 | K4: =9/252 -> 0.035714286 | L4: =H4+G4 -> 101.82 | M4: =$D$31^((-J4)*(K4)) -> 0.99832373 | N4: =I4*M4 -> 94.840754 | O4: =D4+N4 -> 101.64075 | P4: =IF(L4=O4,"Not Violated","Violated") -> Violated | Q4: =ABS(L4-O4) -> 0.17924559 | R4: =D4-G4 -> 6.6300002 | S4: =H4-N4 -> 6.8092458 | T4: =R4-S4 -> -0.17924559 | U4: =O4-H4 -> -0.009245606 | V4: =IF(ABS(G4-U4)<=0.01,"NO VIOLATION",IF(G4>U4,"YES", "NO")) -> YES | W4: =IF(ABS(G4-U4)<=0.01,"NO VIOLATION",IF(G4>U4,"NO", "YES")) -> NO
A5: MRK 11/15/24 C98 | B5: 45423 | C5: 2 | D5: =('Bloomberg Raw Data-5th(No zero)'!C7+'Bloomberg Raw Data-5th(No zero)'!D7)/2 -> 4.2250004 | E5: MRK 11/15/24 P98 | F5: 124 | G5: =('Bloomberg Raw Data-5th(No zero)'!J7+'Bloomberg Raw Data-5th(No zero)'!K7)/2 -> 0.61000001 | H5: 101.65 | I5: 98 | J5: =4.6975/100 -> 0.046975 | K5: =9/252 -> 0.035714286 | L5: =H5+G5 -> 102.26 | M5: =$D$31^((-J5)*(K5)) -> 0.99832373 | N5: =I5*M5 -> 97.835725 | O5: =D5+N5 -> 102.06073 | P5: =IF(L5=O5,"Not Violated","Violated") -> Violated | Q5: =ABS(L5-O5) -> 0.19927424 | R5: =D5-G5 -> 3.6150004 | S5: =H5-N5 -> 3.8142746 | T5: =R5-S5 -> -0.19927424 | U5: =O5-H5 -> 0.41072577 | V5: =IF(ABS(G5-U5)<=0.01,"NO VIOLATION",IF(G5>U5,"YES", "NO")) -> YES | W5: =IF(ABS(G5-U5)<=0.01,"NO VIOLATION",IF(G5>U5,"NO", "YES")) -> NO
A6: MRK 11/15/24 C99 | B6: 45423 | C6: 10 | D6: =('Bloomberg Raw Data-5th(No zero)'!C8+'Bloomberg Raw Data-5th(No zero)'!D8)/2 -> 3.4750004 | E6: MRK 11/15/24 P99 | F6: 56 | G6: =('Bloomberg Raw Data-5th(No zero)'!J8+'Bloomberg Raw Data-5th(No zero)'!K8)/2 -> 0.88 | H6: 101.65 | I6: 99 | J6: =4.6975/100 -> 0.046975 | K6: =9/252 -> 0.035714286 | L6: =H6+G6 -> 102.53 | M6: =$D$31^((-J6)*(K6)) -> 0.99832373 | N6: =I6*M6 -> 98.834049 | O6: =D6+N6 -> 102.30905 | P6: =IF(L6=O6,"Not Violated","Violated") -> Violated | Q6: =ABS(L6-O6) -> 0.2209505 | R6: =D6-G6 -> 2.5950004 | S6: =H6-N6 -> 2.8159509 | T6: =R6-S6 -> -0.2209505 | U6: =O6-H6 -> 0.6590495 | V6: =IF(ABS(G6-U6)<=0.01,"NO VIOLATION",IF(G6>U6,"YES", "NO")) -> YES | W6: =IF(ABS(G6-U6)<=0.01,"NO VIOLATION",IF(G6>U6,"NO", "YES")) -> NO
A7: MRK 11/15/24 C100 | B7: 45423 | C7: 55 | D7: =('Bloomberg Raw Data-5th(No zero)'!C9+'Bloomberg Raw Data-5th(No zero)'!D9)/2 -> 2.7850003 | E7: MRK 11/15/24 P100 | F7: 84 | G7: =('Bloomberg Raw Data-5th(No zero)'!J9+'Bloomberg Raw Data-5th(No zero)'!K9)/2 -> 1.1300001 | H7: 101.65 | I7: 100 | J7: =4.6975/100 -> 0.046975 | K7: =9/252 -> 0.035714286 | L7: =H7+G7 -> 102.78 | M7: =$D$31^((-J7)*(K7)) -> 0.99832373 | N7: =I7*M7 -> 99.832373 | O7: =D7+N7 -> 102.61737 | P7: =IF(L7=O7,"Not Violated","Violated") -> Violated | Q7: =ABS(L7-O7) -> 0.16262694 | R7: =D7-G7 -> 1.6550002 | S7: =H7-N7 -> 1.8176272 | T7: =R7-S7 -> -0.16262694 | U7: =O7-H7 -> 0.96737317 | V7: =IF(ABS(G7-U7)<=0.01,"NO VIOLATION",IF(G7>U7,"YES", "NO")) -> YES | W7: =IF(ABS(G7-U7)<=0.01,"NO VIOLATION",IF(G7>U7,"NO", "YES")) -> NO
A8: MRK 11/15/24 C101 | B8: 45423 | C8: 28 | D8: =('Bloomberg Raw Data-5th(No zero)'!C10+'Bloomberg Raw Data-5th(No zero)'!D10)/2 -> 2.1599998 | E8: MRK 11/15/24 P101 | F8: 100 | G8: =('Bloomberg Raw Data-5th(No zero)'!J10+'Bloomberg Raw Data-5th(No zero)'!K10)/2 -> 1.5499997 | H8: 101.65 | I8: 101 | J8: =4.6975/100 -> 0.046975 | K8: =9/252 -> 0.035714286 | L8: =H8+G8 -> 103.2 | M8: =$D$31^((-J8)*(K8)) -> 0.99832373 | N8: =I8*M8 -> 100.8307 | O8: =D8+N8 -> 102.9907 | P8: =IF(L8=O8,"Not Violated","Violated") -> Violated | Q8: =ABS(L8-O8) -> 0.20930329 | R8: =D8-G8 -> 0.61000013 | S8: =H8-N8 -> 0.81930343 | T8: =R8-S8 -> -0.20930329 | U8: =O8-H8 -> 1.3406964 | V8: =IF(ABS(G8-U8)<=0.01,"NO VIOLATION",IF(G8>U8,"YES", "NO")) -> YES | W8: =IF(ABS(G8-U8)<=0.01,"NO VIOLATION",IF(G8>U8,"NO", "YES")) -> NO
A9: MRK 11/15/24 C102 | B9: 45423 | C9: 41 | D9: =('Bloomberg Raw Data-5th(No zero)'!C11+'Bloomberg Raw Data-5th(No zero)'!D11)/2 -> 1.6299996 | E9: MRK 11/15/24 P102 | F9: 65 | G9: =('Bloomberg Raw Data-5th(No zero)'!J11+'Bloomberg Raw Data-5th(No zero)'!K11)/2 -> 2.0149999 | H9: 101.65 | I9: 102 | J9: =4.6975/100 -> 0.046975 | K9: =9/252 -> 0.035714286 | L9: =H9+G9 -> 103.665 | M9: =$D$31^((-J9)*(K9)) -> 0.99832373 | N9: =I9*M9 -> 101.82902 | O9: =D9+N9 -> 103.45902 | P9: =IF(L9=O9,"Not Violated","Violated") -> Violated | Q9: =ABS(L9-O9) -> 0.20597993 | R9: =D9-G9 -> -0.38500023 | S9: =H9-N9 -> -0.1790203 | T9: =R9-S9 -> -0.20597993 | U9: =O9-H9 -> 1.8090199 | V9: =IF(ABS(G9-U9)<=0.01,"NO VIOLATION",IF(G9>U9,"YES", "NO")) -> YES | W9: =IF(ABS(G9-U9)<=0.01,"NO VIOLATION",IF(G9>U9,"NO", "YES")) -> NO
A10: MRK 11/15/24 C103 | B10: 45423 | C10: 89 | D10: =('Bloomberg Raw Data-5th(No zero)'!C12+'Bloomberg Raw Data-5th(No zero)'!D12)/2 -> 1.1950002 | E10: MRK 11/15/24 P103 | F10: 28 | G10: =('Bloomberg Raw Data-5th(No zero)'!J12+'Bloomberg Raw Data-5th(No zero)'!K12)/2 -> 2.585 | H10: 101.65 | I10: 103 | J10: =4.6975/100 -> 0.046975 | K10: =9/252 -> 0.035714286 | L10: =H10+G10 -> 104.235 | M10: =$D$31^((-J10)*(K10)) -> 0.99832373 | N10: =I10*M10 -> 102.82734 | O10: =D10+N10 -> 104.02234 | P10: =IF(L10=O10,"Not Violated","Violated") -> Violated | Q10: =ABS(L10-O10) -> 0.21265584 | R10: =D10-G10 -> -1.3899999 | S10: =H10-N10 -> -1.177344 | T10: =R10-S10 -> -0.21265584 | U10: =O10-H10 -> 2.3723442 | V10: =IF(ABS(G10-U10)<=0.01,"NO VIOLATION",IF(G10>U10,"YES", "NO")) -> YES | W10: =IF(ABS(G10-U10)<=0.01,"NO VIOLATION",IF(G10>U10,"NO", "YES")) -> NO
A11: MRK 11/15/24 C104 | B11: 45423 | C11: 56 | D11: =('Bloomberg Raw Data-5th(No zero)'!C13+'Bloomberg Raw Data-5th(No zero)'!D13)/2 -> 0.845 | E11: MRK 11/15/24 P104 | F11: 29 | G11: =('Bloomberg Raw Data-5th(No zero)'!J13+'Bloomberg Raw Data-5th(No zero)'!K13)/2 -> 3.2750001 | H11: 101.65 | I11: 104 | J11: =4.6975/100 -> 0.046975 | K11: =9/252 -> 0.035714286 | L11: =H11+G11 -> 104.925 | M11: =$D$31^((-J11)*(K11)) -> 0.99832373 | N11: =I11*M11 -> 103.82567 | O11: =D11+N11 -> 104.67067 | P11: =IF(L11=O11,"Not Violated","Violated") -> Violated | Q11: =ABS(L11-O11) -> 0.25433234 | R11: =D11-G11 -> -2.4300001 | S11: =H11-N11 -> -2.1756678 | T11: =R11-S11 -> -0.25433234 | U11: =O11-H11 -> 3.0206678 | V11: =IF(ABS(G11-U11)<=0.01,"NO VIOLATION",IF(G11>U11,"YES", "NO")) -> YES | W11: =IF(ABS(G11-U11)<=0.01,"NO VIOLATION",IF(G11>U11,"NO", "YES")) -> NO
A12: MRK 11/15/24 C105 | B12: 45423 | C12: 660 | D12: =('Bloomberg Raw Data-5th(No zero)'!C14+'Bloomberg Raw Data-5th(No zero)'!D14)/2 -> 0.59 | E12: MRK 11/15/24 P105 | F12: 69 | G12: =('Bloomberg Raw Data-5th(No zero)'!J14+'Bloomberg Raw Data-5th(No zero)'!K14)/2 -> 4 | H12: 101.65 | I12: 105 | J12: =4.6975/100 -> 0.046975 | K12: =9/252 -> 0.035714286 | L12: =H12+G12 -> 105.65 | M12: =$D$31^((-J12)*(K12)) -> 0.99832373 | N12: =I12*M12 -> 104.82399 | O12: =D12+N12 -> 105.41399 | P12: =IF(L12=O12,"Not Violated","Violated") -> Violated | Q12: =ABS(L12-O12) -> 0.23600851 | R12: =D12-G12 -> -3.41 | S12: =H12-N12 -> -3.1739915 | T12: =R12-S12 -> -0.23600851 | U12: =O12-H12 -> 3.7639915 | V12: =IF(ABS(G12-U12)<=0.01,"NO VIOLATION",IF(G12>U12,"YES", "NO")) -> YES | W12: =IF(ABS(G12-U12)<=0.01,"NO VIOLATION",IF(G12>U12,"NO", "YES")) -> NO
A13: MRK 11/15/24 C106 | B13: 45423 | C13: 107 | D13: =('Bloomberg Raw Data-5th(No zero)'!C15+'Bloomberg Raw Data-5th(No zero)'!D15)/2 -> 0.405 | E13: MRK 11/15/24 P106 | F13: 11 | G13: =('Bloomberg Raw Data-5th(No zero)'!J15+'Bloomberg Raw Data-5th(No zero)'!K15)/2 -> 4.8500004 | H13: 101.65 | I13: 106 | J13: =4.6975/100 -> 0.046975 | K13: =9/252 -> 0.035714286 | L13: =H13+G13 -> 106.5 | M13: =$D$31^((-J13)*(K13)) -> 0.99832373 | N13: =I13*M13 -> 105.82232 | O13: =D13+N13 -> 106.22732 | P13: =IF(L13=O13,"Not Violated","Violated") -> Violated | Q13: =ABS(L13-O13) -> 0.27268516 | R13: =D13-G13 -> -4.4450004 | S13: =H13-N13 -> -4.1723152 | T13: =R13-S13 -> -0.27268516 | U13: =O13-H13 -> 4.5773152 | V13: =IF(ABS(G13-U13)<=0.01,"NO VIOLATION",IF(G13>U13,"YES", "NO")) -> YES | W13: =IF(ABS(G13-U13)<=0.01,"NO VIOLATION",IF(G13>U13,"NO", "YES")) -> NO
A14: MRK 11/15/24 C107 | B14: 45423 | C14: 36 | D14: =('Bloomberg Raw Data-5th(No zero)'!C16+'Bloomberg Raw Data-5th(No zero)'!D16)/2 -> 0.26500002 | E14: MRK 11/15/24 P107 | F14: 6 | G14: =('Bloomberg Raw Data-5th(No zero)'!J16+'Bloomberg Raw Data-5th(No zero)'!K16)/2 -> 5.7250004 | H14: 101.65 | I14: 107 | J14: =4.6975/100 -> 0.046975 | K14: =9/252 -> 0.035714286 | L14: =H14+G14 -> 107.375 | M14: =$D$31^((-J14)*(K14)) -> 0.99832373 | N14: =I14*M14 -> 106.82064 | O14: =D14+N14 -> 107.08564 | P14: =IF(L14=O14,"Not Violated","Violated") -> Violated | Q14: =ABS(L14-O14) -> 0.28936142 | R14: =D14-G14 -> -5.4600004 | S14: =H14-N14 -> -5.1706389 | T14: =R14-S14 -> -0.28936142 | U14: =O14-H14 -> 5.435639 | V14: =IF(ABS(G14-U14)<=0.01,"NO VIOLATION",IF(G14>U14,"YES", "NO")) -> YES | W14: =IF(ABS(G14-U14)<=0.01,"NO VIOLATION",IF(G14>U14,"NO", "YES")) -> NO
A15: MRK 11/15/24 C110 | B15: 45423 | C15: 114 | D15: =('Bloomberg Raw Data-5th(No zero)'!C17+'Bloomberg Raw Data-5th(No zero)'!D17)/2 -> 0.10500002 | E15: MRK 11/15/24 P110 | F15: 143 | G15: =('Bloomberg Raw Data-5th(No zero)'!J17+'Bloomberg Raw Data-5th(No zero)'!K17)/2 -> 8.5999999 | H15: 101.65 | I15: 110 | J15: =4.6975/100 -> 0.046975 | K15: =9/252 -> 0.035714286 | L15: =H15+G15 -> 110.25 | M15: =$D$31^((-J15)*(K15)) -> 0.99832373 | N15: =I15*M15 -> 109.81561 | O15: =D15+N15 -> 109.92061 | P15: =IF(L15=O15,"Not Violated","Violated") -> Violated | Q15: =ABS(L15-O15) -> 0.32938976 | R15: =D15-G15 -> -8.4949999 | S15: =H15-N15 -> -8.1656101 | T15: =R15-S15 -> -0.32938976 | U15: =O15-H15 -> 8.2706101 | V15: =IF(ABS(G15-U15)<=0.01,"NO VIOLATION",IF(G15>U15,"YES", "NO")) -> YES | W15: =IF(ABS(G15-U15)<=0.01,"NO VIOLATION",IF(G15>U15,"NO", "YES")) -> NO
... A17: MRK 11/15/24 C130 | B17: 45423 | C17: 10 | D17: =('Bloomberg Raw Data-5th(No zero)'!C19+'Bloomberg Raw Data-5th(No zero)'!D19)/2 -> 0.02 | E17: MRK 11/15/24 P130 | F17: 4 | G17: =('Bloomberg Raw Data-5th(No zero)'!J19+'Bloomberg Raw Data-5th(No zero)'!K19)/2 -> 28.899994 | H17: 101.65 | I17: 130 | J17: =4.6975/100 -> 0.046975 | K17: =9/252 -> 0.035714286 | L17: =H17+G17 -> 130.54999 | M17: =$D$31^((-J17)*(K17)) -> 0.99832373 | N17: =I17*M17 -> 129.78208 | O17: =D17+N17 -> 129.80208 | P17: =IF(L17=O17,"Not Violated","Violated") -> Violated | Q17: =ABS(L17-O17) -> 0.7479092 | R17: =D17-G17 -> -28.879994 | S17: =H17-N17 -> -28.132085 | T17: =R17-S17 -> -0.7479092 | U17: =O17-H17 -> 28.152085 | V17: =IF(ABS(G17-U17)<=0.01,"NO VIOLATION",IF(G17>U17,"YES", "NO")) -> YES | W17: =IF(ABS(G17-U17)<=0.01,"NO VIOLATION",IF(G17>U17,"NO", "YES")) -> NO
A20: #Arbitrage Strategy Analysis for MRK 11/15/24 C102: Validating Overpriced Option via Put-Call Parity
A22: Category | B22: Parameter | D22: Value | F22: Category | G22: Parameter | I22: Value | L22: Factors Impacting Arbitrage Feasibility:
A23: Put-Call Parity Relationship | B23: C − P = S− K*e^−r(T−t) | D23: Alternatively formula can be written as S+P = C+ K*e^−r(T−t) | F23: Situation | L23: Risks to Arbitrage | M23: 1. Execution Risks - Arbitrage depends on the simultaneous execution of several trades. Any delay might lead to price fluctuations, negating potential gains sanction Cost - Brokerage fees and bid-ask spreads can quickly erode small profits.
F24: C−P (Observed) < S−K*e^−r(T−t) (Theoretical) → Overpriced Scenario | G24: Results | I24: Overpriced Scenario | M24: 2. Transaction Costs - Fees from brokers and the difference between bid and ask prices can quickly diminish small profit margins.
A25: Market Data on November 5, 2024 | B25: Price of the CALL Option (C) | D25: =D9 -> 1.6299996 | F25: C−P (Observed) > S−K*e^−r(T−t) (Theoretical) → Underpriced Scenario | M25: 3. European Options - This analysis is based on European-style options. In contrast, American-style options, which can be exercised anytime, may interfere with the strategy.
B26: Price of the PUT Option (P) | D26: =G9 -> 2.0149999 | F26: Arbitrage Strategy | G26: A. Initial Cash Flow: | M26: 4. Liquidity - Low open interest and trading volume for some options can increase the risk of slippage or incomplete transactions.
B27: Current Stock Price (S) | D27: =H9 -> 101.65 | G27: Buy Call | I27: =-D9 -> -1.6299996
B28: Strike Price of the Option (K) | D28: =I9 -> 102 | G28: Sell Put | I28: =G9 -> 2.0149999
B29: Risk-Free Interest Rate (r) | D29: =J4 -> 0.046975 | G29: Short Stock | I29: 101.65
B30: Time to Expiration (T-t) | D30: =9/252 -> 0.035714286 | G30: Invest in Bonds (PV of Strike Price) | I30: =-N9 -> -101.82902
B31: Constant e | D31: 2.718281 | G31: Net Initial Cash Flow | I31: =SUM(I27:I30) -> 0.20597993
A32: Discounted Strike Price | B32: {PV(K) = K*e^−r(T−t)} | D32: =D28*D31^(-D29*D30) -> 101.82902
D33: (102)*e^(-4.6975%*0.035714) | F33: Underlying Price as of November 15, 2024 | G33: ='Bloomberg Raw Data-5th(No zero)'!I54 -> 96.31
A34: Empirical Value | B34: [ C - P ] | D34: =D25-D26 -> -0.38500023 | G34: Net Payoff | I34: =I31 -> 0.20597993
A35: Model Value | B35: [ S - K*e^−r(T−t) ] | D35: =S9 -> -0.1790203 | F35: Arbitrage Strategy (At Expiration) When my Stock price (S) < Strike Price (K), we can exercise the put and sell the at K (102). This strategy allows us to cover the short position(96.31). The bonds will mature to K(102), ensuring sufficient funds are maintained to cover all liabilities. Thus, The call expires worthless, avoiding additional costs
A36: PUT-CALL Parity Violation | B36: [ Deviation ] | D36: =D34-D35 -> -0.20597993
D37: Potential Arbitrage Opportunity
G41: Net Payoff | I41: =I31 -> 0.20597993
A42: Option Arbitrage Strategies: Steps for Overpriced and Underpriced Scenarios
A44: Scenario | B44: Step and Description
A45: Overpriced Stock (S + P > C + K⋅e^−r(T−t)) | B45: 1.Identify Mispricing: Compare market and theoretical values to confirm mispricing
B46: 2.Short the stock: Benefit from the expected price drop
B47: 3.Sell overpriced put: Lock in inflated premiums
B48: 4.Buy a call option: Hedge against unexpected price increases
...

Sheet Q1. Put- Call Parity(With zero 
B2: A. PUT-CALL Partity for all Options as on November 5, 2024
R3: Arbirtage Startegy | U3: Category | V3: Parameter | X3: Value | Z3: Category | AA3: Parameter | AC3: Value | AF3: Factors Impacting Arbitrage Feasibility:
B4: Option Symbol | C4: Option Expiry Date (EDT) | D4: Call Price( Bid and ask Average) ( C ) | E4: ='Q1-(Without Zero Volume)'!G3 -> Put Price (P) ( Bid and ask Average)\ | F4: C - P | G4: ='Q1-(Without Zero Volume)'!H3 -> Stock Price/ Spot Price (S) | H4: ='Q1-(Without Zero Volume)'!I3 -> Strike Price (K) | I4: e^-r(T-t) | J4: K*e^-r(T-t) | K4: S - K*e^-r(T-t) | L4: Difference | M4: CALL+Strike*e^(-rt) | N4: Put+Spot | O4: Difference | P4: Violation of Put-Call parity | Q4: Theoretical Value of Put Option P=C+K*e^-rt-S | R4: S+P>C+K⋅e ^−r(T−t) (OVERVALUED) | S4: S+P<C+K⋅e ^−r(T−t) (UNDERVALUED) | U4: Put-Call Parity Relationship | V4: C − P = S− K*e^−r(T−t) | X4: Alternatively formula can be written as S+P = C+ K*e^−r(T−t) | Z4: Situation | AF4: Risks to Arbitrage | AG4: 1. Execution Risks - Arbitrage depends on the simultaneous execution of several trades. Any delay might lead to price fluctuations, negating potential gains.nsaction Cost - Brokerage fees and bid-ask spreads can quickly erode small profits.
B5: MRK241115C00060000 | C5: 45558.775 | D5: =('Bloomberg Raw Data-5th (2)'!C8+'Bloomberg Raw Data-5th (2)'!D8)/2 -> 41.675003 | E5: =('Bloomberg Raw Data-5th (2)'!J8+'Bloomberg Raw Data-5th (2)'!K8)/2 -> 0.14000002 | F5: =D5-E5 -> 41.535003 | G5: 101.65 | H5: ='Bloomberg Raw Data-5th (2)'!A8 -> 60 | I5: =2.718281^(-$X$10*$X$11) -> 0.99832373 | J5: =H5*I5 -> 59.899424 | K5: =G5-J5 -> 41.750576 | L5: =F5-K5 -> -0.21557326 | M5: =D5+J5 -> 101.57443 | N5: =E5+G5 -> 101.79 | O5: =M5-N5 -> -0.21557326 | P5: =IF(M5=N5,"Not Violated","Voilated") -> Voilated | Q5: =M5-G5 -> -0.075573241 | R5: =IF(ABS(E5-Q5)<=0.01,"NO VIOLATION",IF(E5>Q5,"YES", "NO")) -> YES | S5: =IF(ABS(E5-Q5)<=0.01,"NO VIOLATION",IF(E5>Q5,"NO", "YES")) -> NO | Z5: C−P (Observed) < S−K*e^−r(T−t) (Theoretical) → Underpricing Scenario | AA5: Results | AC5: Underpricing Scenario | AG5: 2. Transaction Costs - Fees from brokers and the difference between bid and ask prices can quickly diminish small profit margins.
B6: MRK241115C00070000 | C6: 45574.588 | D6: =('Bloomberg Raw Data-5th (2)'!C9+'Bloomberg Raw Data-5th (2)'!D9)/2 -> 31.649994 | E6: =('Bloomberg Raw Data-5th (2)'!J9+'Bloomberg Raw Data-5th (2)'!K9)/2 -> 0.14500001 | F6: =D6-E6 -> 31.504994 | G6: =G5 -> 101.65 | H6: ='Bloomberg Raw Data-5th (2)'!A9 -> 70 | I6: =2.718281^(-$X$10*$X$11) -> 0.99832373 | J6: =H6*I6 -> 69.882661 | K6: =G6-J6 -> 31.767339 | L6: =F6-K6 -> -0.26234512 | M6: =D6+J6 -> 101.53265 | N6: =E6+G6 -> 101.795 | O6: =M6-N6 -> -0.26234512 | P6: =IF(M6=N6,"Not Violated","Voilated") -> Voilated | Q6: =M6-G6 -> -0.11734511 | R6: =IF(ABS(E6-Q6)<=0.01,"NO VIOLATION",IF(E6>Q6,"YES", "NO")) -> YES | S6: =IF(ABS(E6-Q6)<=0.01,"NO VIOLATION",IF(E6>Q6,"NO", "YES")) -> NO | U6: Market Data on November 5, 2024 | V6: Price of the CALL Option (C) | X6: =D15 -> 1.6299996 | Z6: C−P (Observed) > S−K*e^−r(T−t) (Theoretical) → Overpricing Scenario | AG6: 3. European Options - This analysis is based on European-style options. In contrast, American-style options, which can be exercised anytime, may interfere with the strategy.
B7: MRK241115C00080000 | C7: 45596.817 | D7: =('Bloomberg Raw Data-5th (2)'!C10+'Bloomberg Raw Data-5th (2)'!D10)/2 -> 21.674995 | E7: =('Bloomberg Raw Data-5th (2)'!J10+'Bloomberg Raw Data-5th (2)'!K10)/2 -> 0.064999998 | F7: =D7-E7 -> 21.609995 | G7: =G6 -> 101.65 | H7: ='Bloomberg Raw Data-5th (2)'!A10 -> 80 | I7: =2.718281^(-$X$10*$X$11) -> 0.99832373 | J7: =H7*I7 -> 79.865898 | K7: =G7-J7 -> 21.784102 | L7: =F7-K7 -> -0.1741063 | M7: =D7+J7 -> 101.54089 | N7: =E7+G7 -> 101.715 | O7: =M7-N7 -> -0.1741063 | P7: =IF(M7=N7,"Not Violated","Voilated") -> Voilated | Q7: =M7-G7 -> -0.1091063 | R7: =IF(ABS(E7-Q7)<=0.01,"NO VIOLATION",IF(E7>Q7,"YES", "NO")) -> YES | S7: =IF(ABS(E7-Q7)<=0.01,"NO VIOLATION",IF(E7>Q7,"NO", "YES")) -> NO | V7: Price of the PUT Option (P) | X7: =E15 -> 2.0149999 | Z7: Arbitrage Strategy | AA7: A. Initial Cash Flow: | AG7: 4. Liquidity - Low open interest and trading volume for some options can increase the risk of slippage or incomplete transactions.
B8: MRK241115C00085000 | C8: 45600.701 | D8: =('Bloomberg Raw Data-5th (2)'!C11+'Bloomberg Raw Data-5th (2)'!D11)/2 -> 16.599998 | E8: =('Bloomberg Raw Data-5th (2)'!J11+'Bloomberg Raw Data-5th (2)'!K11)/2 -> 0.050000012 | F8: =D8-E8 -> 16.549998 | G8: =G7 -> 101.65 | H8: ='Bloomberg Raw Data-5th (2)'!A11 -> 85 | I8: =2.718281^(-$X$10*$X$11) -> 0.99832373 | J8: =H8*I8 -> 84.857517 | K8: =G8-J8 -> 16.792483 | L8: =F8-K8 -> -0.24248462 | M8: =D8+J8 -> 101.45752 | N8: =E8+G8 -> 101.7 | O8: =M8-N8 -> -0.24248462 | P8: =IF(M8=N8,"Not Violated","Voilated") -> Voilated | Q8: =M8-G8 -> -0.19248461 | R8: =IF(ABS(E8-Q8)<=0.01,"NO VIOLATION",IF(E8>Q8,"YES", "NO")) -> YES | S8: =IF(ABS(E8-Q8)<=0.01,"NO VIOLATION",IF(E8>Q8,"NO", "YES")) -> NO | V8: Current Stock Price (S) | X8: =G15 -> 101.65 | AA8: Buy Call | AC8: =-$D$15 -> -1.6299996
B9: MRK241115C00090000 | C9: 45589.61 | D9: =('Bloomberg Raw Data-5th (2)'!C12+'Bloomberg Raw Data-5th (2)'!D12)/2 -> 11.65 | E9: =('Bloomberg Raw Data-5th (2)'!J12+'Bloomberg Raw Data-5th (2)'!K12)/2 -> 0.050000017 | F9: =D9-E9 -> 11.6 | G9: =G8 -> 101.65 | H9: ='Bloomberg Raw Data-5th (2)'!A12 -> 90 | I9: =2.718281^(-$X$10*$X$11) -> 0.99832373 | J9: =H9*I9 -> 89.849136 | K9: =G9-J9 -> 11.800864 | L9: =F9-K9 -> -0.20086436 | M9: =D9+J9 -> 101.49914 | N9: =E9+G9 -> 101.7 | O9: =M9-N9 -> -0.20086436 | P9: =IF(M9=N9,"Not Violated","Voilated") -> Voilated | Q9: =M9-G9 -> -0.15086434 | R9: =IF(ABS(E9-Q9)<=0.01,"NO VIOLATION",IF(E9>Q9,"YES", "NO")) -> YES | S9: =IF(ABS(E9-Q9)<=0.01,"NO VIOLATION",IF(E9>Q9,"NO", "YES")) -> NO | V9: Strike Price of the Option (K) | X9: =H15 -> 102 | AA9: Sell Put | AC9: =$E$15 -> 2.0149999
B10: MRK241115C00095000 | C10: 45601.621 | D10: =('Bloomberg Raw Data-5th (2)'!C13+'Bloomberg Raw Data-5th (2)'!D13)/2 -> 6.8000002 | E10: =('Bloomberg Raw Data-5th (2)'!J13+'Bloomberg Raw Data-5th (2)'!K13)/2 -> 0.16999999 | F10: =D10-E10 -> 6.6300002 | G10: =G9 -> 101.65 | H10: ='Bloomberg Raw Data-5th (2)'!A13 -> 95 | I10: =2.718281^(-$X$10*$X$11) -> 0.99832373 | J10: =H10*I10 -> 94.840754 | K10: =G10-J10 -> 6.8092458 | L10: =F10-K10 -> -0.17924559 | M10: =D10+J10 -> 101.64075 | N10: =E10+G10 -> 101.82 | O10: =M10-N10 -> -0.17924559 | P10: =IF(M10=N10,"Not Violated","Voilated") -> Voilated | Q10: =M10-G10 -> -0.009245606 | R10: =IF(ABS(E10-Q10)<=0.01,"NO VIOLATION",IF(E10>Q10,"YES", "NO")) -> YES | S10: =IF(ABS(E10-Q10)<=0.01,"NO VIOLATION",IF(E10>Q10,"NO", "YES")) -> NO | V10: Risk-Free Interest Rate (r) | X10: ='Q2. Implied Volatality - Final'!I8 -> 0.046975 | AA10: Short Stock | AC10: 101.65 | AD10: ***Note: This is the arbitrage profit per contract, assuming no transaction costs.
B11: MRK241115C00098000 | C11: 45597.675 | D11: =('Bloomberg Raw Data-5th (2)'!C14+'Bloomberg Raw Data-5th (2)'!D14)/2 -> 4.2250004 | E11: =('Bloomberg Raw Data-5th (2)'!J14+'Bloomberg Raw Data-5th (2)'!K14)/2 -> 0.61000001 | F11: =D11-E11 -> 3.6150004 | G11: =G10 -> 101.65 | H11: ='Bloomberg Raw Data-5th (2)'!A14 -> 98 | I11: =2.718281^(-$X$10*$X$11) -> 0.99832373 | J11: =H11*I11 -> 97.835725 | K11: =G11-J11 -> 3.8142746 | L11: =F11-K11 -> -0.19927424 | M11: =D11+J11 -> 102.06073 | N11: =E11+G11 -> 102.26 | O11: =M11-N11 -> -0.19927424 | P11: =IF(M11=N11,"Not Violated","Voilated") -> Voilated | Q11: =M11-G11 -> 0.41072577 | R11: =IF(ABS(E11-Q11)<=0.01,"NO VIOLATION",IF(E11>Q11,"YES", "NO")) -> YES | S11: =IF(ABS(E11-Q11)<=0.01,"NO VIOLATION",IF(E11>Q11,"NO", "YES")) -> NO | V11: Time to Expiration (T-t) | X11: =9/252 -> 0.035714286 | AA11: Invest in Bonds (PV of Strike Price) | AC11: =-$J$15 -> -101.82902
B12: MRK241115C00099000 | C12: 45600.629 | D12: =('Bloomberg Raw Data-5th (2)'!C15+'Bloomberg Raw Data-5th (2)'!D15)/2 -> 3.4750004 | E12: =('Bloomberg Raw Data-5th (2)'!J15+'Bloomberg Raw Data-5th (2)'!K15)/2 -> 0.88 | F12: =D12-E12 -> 2.5950004 | G12: =G11 -> 101.65 | H12: ='Bloomberg Raw Data-5th (2)'!A15 -> 99 | I12: =2.718281^(-$X$10*$X$11) -> 0.99832373 | J12: =H12*I12 -> 98.834049 | K12: =G12-J12 -> 2.8159509 | L12: =F12-K12 -> -0.2209505 | M12: =D12+J12 -> 102.30905 | N12: =E12+G12 -> 102.53 | O12: =M12-N12 -> -0.2209505 | P12: =IF(M12=N12,"Not Violated","Voilated") -> Voilated | Q12: =M12-G12 -> 0.6590495 | R12: =IF(ABS(E12-Q12)<=0.01,"NO VIOLATION",IF(E12>Q12,"YES", "NO")) -> YES | S12: =IF(ABS(E12-Q12)<=0.01,"NO VIOLATION",IF(E12>Q12,"NO", "YES")) -> NO | V12: Constant e | X12: 2.718281 | AA12: Net Initial Cash Flow | AC12: =SUM(AC8:AC11) -> 0.20597993
B13: MRK241115C00100000 | C13: 45601.636 | D13: =('Bloomberg Raw Data-5th (2)'!C16+'Bloomberg Raw Data-5th (2)'!D16)/2 -> 2.7850003 | E13: =('Bloomberg Raw Data-5th (2)'!J16+'Bloomberg Raw Data-5th (2)'!K16)/2 -> 1.1300001 | F13: =D13-E13 -> 1.6550002 | G13: =G12 -> 101.65 | H13: ='Bloomberg Raw Data-5th (2)'!A16 -> 100 | I13: =2.718281^(-$X$10*$X$11) -> 0.99832373 | J13: =H13*I13 -> 99.832373 | K13: =G13-J13 -> 1.8176272 | L13: =F13-K13 -> -0.16262694 | M13: =D13+J13 -> 102.61737 | N13: =E13+G13 -> 102.78 | O13: =M13-N13 -> -0.16262694 | P13: =IF(M13=N13,"Not Violated","Voilated") -> Voilated | Q13: =M13-G13 -> 0.96737317 | R13: =IF(ABS(E13-Q13)<=0.01,"NO VIOLATION",IF(E13>Q13,"YES", "NO")) -> YES | S13: =IF(ABS(E13-Q13)<=0.01,"NO VIOLATION",IF(E13>Q13,"NO", "YES")) -> NO | U13: Discounted Strike Price | V13: {PV(K) = K*e^−r(T−t)} | X13: =X9*X12^(-X10*X11) -> 101.82902
B14: MRK241115C00101000 | C14: 45601.644 | D14: =('Bloomberg Raw Data-5th (2)'!C17+'Bloomberg Raw Data-5th (2)'!D17)/2 -> 2.1599998 | E14: =('Bloomberg Raw Data-5th (2)'!J17+'Bloomberg Raw Data-5th (2)'!K17)/2 -> 1.5499997 | F14: =D14-E14 -> 0.61000013 | G14: =G13 -> 101.65 | H14: ='Bloomberg Raw Data-5th (2)'!A17 -> 101 | I14: =2.718281^(-$X$10*$X$11) -> 0.99832373 | J14: =H14*I14 -> 100.8307 | K14: =G14-J14 -> 0.81930343 | L14: =F14-K14 -> -0.20930329 | M14: =D14+J14 -> 102.9907 | N14: =E14+G14 -> 103.2 | O14: =M14-N14 -> -0.20930329 | P14: =IF(M14=N14,"Not Violated","Voilated") -> Voilated | Q14: =M14-G14 -> 1.3406964 | R14: =IF(ABS(E14-Q14)<=0.01,"NO VIOLATION",IF(E14>Q14,"YES", "NO")) -> YES | S14: =IF(ABS(E14-Q14)<=0.01,"NO VIOLATION",IF(E14>Q14,"NO", "YES")) -> NO | X14: (102)*e^(-4.6975%*0.039683) | Z14: Underlying Price as of November 15, 2024 | AA14: ='Bloomberg Raw Data-5th(No zero)'!I54 -> 96.31
B15: MRK241115C00102000 | C15: 45601.618 | D15: =('Bloomberg Raw Data-5th (2)'!C18+'Bloomberg Raw Data-5th (2)'!D18)/2 -> 1.6299996 | E15: =('Bloomberg Raw Data-5th (2)'!J18+'Bloomberg Raw Data-5th (2)'!K18)/2 -> 2.0149999 | F15: =D15-E15 -> -0.38500023 | G15: =G14 -> 101.65 | H15: ='Bloomberg Raw Data-5th (2)'!A18 -> 102 | I15: =2.718281^(-$X$10*$X$11) -> 0.99832373 | J15: =H15*I15 -> 101.82902 | K15: =G15-J15 -> -0.1790203 | L15: =F15-K15 -> -0.20597993 | M15: =D15+J15 -> 103.45902 | N15: =E15+G15 -> 103.665 | O15: =M15-N15 -> -0.20597993 | P15: =IF(M15=N15,"Not Violated","Voilated") -> Voilated | Q15: =M15-G15 -> 1.8090199 | R15: =IF(ABS(E15-Q15)<=0.01,"NO VIOLATION",IF(E15>Q15,"YES", "NO")) -> YES | S15: =IF(ABS(E15-Q15)<=0.01,"NO VIOLATION",IF(E15>Q15,"NO", "YES")) -> NO | U15: Empirical Value | V15: [ C - P ] | X15: =X6-X7 -> -0.38500023
B16: MRK241115C00103000 | C16: 45601.642 | D16: =('Bloomberg Raw Data-5th (2)'!C19+'Bloomberg Raw Data-5th (2)'!D19)/2 -> 1.1950002 | E16: =('Bloomberg Raw Data-5th (2)'!J19+'Bloomberg Raw Data-5th (2)'!K19)/2 -> 2.585 | F16: =D16-E16 -> -1.3899999 | G16: =G15 -> 101.65 | H16: ='Bloomberg Raw Data-5th (2)'!A19 -> 103 | I16: =2.718281^(-$X$10*$X$11) -> 0.99832373 | J16: =H16*I16 -> 102.82734 | K16: =G16-J16 -> -1.177344 | L16: =F16-K16 -> -0.21265584 | M16: =D16+J16 -> 104.02234 | N16: =E16+G16 -> 104.235 | O16: =M16-N16 -> -0.21265584 | P16: =IF(M16=N16,"Not Violated","Voilated") -> Voilated | Q16: =M16-G16 -> 2.3723442 | R16: =IF(ABS(E16-Q16)<=0.01,"NO VIOLATION",IF(E16>Q16,"YES", "NO")) -> YES | S16: =IF(ABS(E16-Q16)<=0.01,"NO VIOLATION",IF(E16>Q16,"NO", "YES")) -> NO | U16: Model Value | V16: [ S - K*e^−r(T−t) ] | X16: =K15 -> -0.1790203 | Z16: Arbitrage Strategy | AA16: B. At Expiration
B17: MRK241115C00104000 | C17: 45601.618 | D17: =('Bloomberg Raw Data-5th (2)'!C20+'Bloomberg Raw Data-5th (2)'!D20)/2 -> 0.845 | E17: =('Bloomberg Raw Data-5th (2)'!J20+'Bloomberg Raw Data-5th (2)'!K20)/2 -> 3.2750001 | F17: =D17-E17 -> -2.4300001 | G17: =G16 -> 101.65 | H17: ='Bloomberg Raw Data-5th (2)'!A20 -> 104 | I17: =2.718281^(-$X$10*$X$11) -> 0.99832373 | J17: =H17*I17 -> 103.82567 | K17: =G17-J17 -> -2.1756678 | L17: =F17-K17 -> -0.25433234 | M17: =D17+J17 -> 104.67067 | N17: =E17+G17 -> 104.925 | O17: =M17-N17 -> -0.25433234 | P17: =IF(M17=N17,"Not Violated","Voilated") -> Voilated | Q17: =M17-G17 -> 3.0206678 | R17: =IF(ABS(E17-Q17)<=0.01,"NO VIOLATION",IF(E17>Q17,"YES", "NO")) -> YES | S17: =IF(ABS(E17-Q17)<=0.01,"NO VIOLATION",IF(E17>Q17,"NO", "YES")) -> NO | U17: PUT-CALL Parity Violation | V17: [ Deviation ] | X17: =L15 -> -0.20597993 | AA17: Stock Prics < Strike Price | AC17: The put option is excercised
B18: MRK241115C00105000 | C18: 45601.647 | D18: =('Bloomberg Raw Data-5th (2)'!C21+'Bloomberg Raw Data-5th (2)'!D21)/2 -> 0.59 | E18: =('Bloomberg Raw Data-5th (2)'!J21+'Bloomberg Raw Data-5th (2)'!K21)/2 -> 4 | F18: =D18-E18 -> -3.41 | G18: =G17 -> 101.65 | H18: ='Bloomberg Raw Data-5th (2)'!A21 -> 105 | I18: =2.718281^(-$X$10*$X$11) -> 0.99832373 | J18: =H18*I18 -> 104.82399 | K18: =G18-J18 -> -3.1739915 | L18: =F18-K18 -> -0.23600851 | M18: =D18+J18 -> 105.41399 | N18: =E18+G18 -> 105.65 | O18: =M18-N18 -> -0.23600851 | P18: =IF(M18=N18,"Not Violated","Voilated") -> Voilated | Q18: =M18-G18 -> 3.7639915 | R18: =IF(ABS(E18-Q18)<=0.01,"NO VIOLATION",IF(E18>Q18,"YES", "NO")) -> YES | S18: =IF(ABS(E18-Q18)<=0.01,"NO VIOLATION",IF(E18>Q18,"NO", "YES")) -> NO | X18: Potential Arbitrage Opportunity | AC18: Sell stock at K=102.
B19: MRK241115C00106000 | C19: 45601.646 | D19: =('Bloomberg Raw Data-5th (2)'!C22+'Bloomberg Raw Data-5th (2)'!D22)/2 -> 0.405 | E19: =('Bloomberg Raw Data-5th (2)'!J22+'Bloomberg Raw Data-5th (2)'!K22)/2 -> 4.8500004 | F19: =D19-E19 -> -4.4450004 | G19: =G18 -> 101.65 | H19: ='Bloomberg Raw Data-5th (2)'!A22 -> 106 | I19: =2.718281^(-$X$10*$X$11) -> 0.99832373 | J19: =H19*I19 -> 105.82232 | K19: =G19-J19 -> -4.1723152 | L19: =F19-K19 -> -0.27268516 | M19: =D19+J19 -> 106.22732 | N19: =E19+G19 -> 106.5 | O19: =M19-N19 -> -0.27268516 | P19: =IF(M19=N19,"Not Violated","Voilated") -> Voilated | Q19: =M19-G19 -> 4.5773152 | R19: =IF(ABS(E19-Q19)<=0.01,"NO VIOLATION",IF(E19>Q19,"YES", "NO")) -> YES | S19: =IF(ABS(E19-Q19)<=0.01,"NO VIOLATION",IF(E19>Q19,"NO", "YES")) -> NO | AC19: The call option expires worthless.
B20: MRK241115C00107000 | C20: 45600.875 | D20: =('Bloomberg Raw Data-5th (2)'!C23+'Bloomberg Raw Data-5th (2)'!D23)/2 -> 0.26500002 | E20: =('Bloomberg Raw Data-5th (2)'!J23+'Bloomberg Raw Data-5th (2)'!K23)/2 -> 5.7250004 | F20: =D20-E20 -> -5.4600004 | G20: =G19 -> 101.65 | H20: ='Bloomberg Raw Data-5th (2)'!A23 -> 107 | I20: =2.718281^(-$X$10*$X$11) -> 0.99832373 | J20: =H20*I20 -> 106.82064 | K20: =G20-J20 -> -5.1706389 | L20: =F20-K20 -> -0.28936142 | M20: =D20+J20 -> 107.08564 | N20: =E20+G20 -> 107.375 | O20: =M20-N20 -> -0.28936142 | P20: =IF(M20=N20,"Not Violated","Voilated") -> Voilated | Q20: =M20-G20 -> 5.435639 | R20: =IF(ABS(E20-Q20)<=0.01,"NO VIOLATION",IF(E20>Q20,"YES", "NO")) -> YES | S20: =IF(ABS(E20-Q20)<=0.01,"NO VIOLATION",IF(E20>Q20,"NO", "YES")) -> NO | AC20: Short stock is covered at K=96.31
B21: MRK241115C00108000 | C21: 45601.623 | D21: =('Bloomberg Raw Data-5th (2)'!C24+'Bloomberg Raw Data-5th (2)'!D24)/2 -> 0.19 | E21: =('Bloomberg Raw Data-5th (2)'!J24+'Bloomberg Raw Data-5th (2)'!K24)/2 -> 5.9750004 | F21: =D21-E21 -> -5.7850004 | G21: =G20 -> 101.65 | H21: ='Bloomberg Raw Data-5th (2)'!A24 -> 108 | I21: =2.718281^(-$X$10*$X$11) -> 0.99832373 | J21: =H21*I21 -> 107.81896 | K21: =G21-J21 -> -6.1689627 | L21: =F21-K21 -> 0.38396229 | M21: =D21+J21 -> 108.00896 | N21: =E21+G21 -> 107.625 | O21: =M21-N21 -> 0.38396229 | P21: =IF(M21=N21,"Not Violated","Voilated") -> Voilated | Q21: =M21-G21 -> 6.3589627 | R21: =IF(ABS(E21-Q21)<=0.01,"NO VIOLATION",IF(E21>Q21,"YES", "NO")) -> NO | S21: =IF(ABS(E21-Q21)<=0.01,"NO VIOLATION",IF(E21>Q21,"NO", "YES")) -> YES | AC21: Bonds mature to K=102
B22: MRK241115C00109000 | C22: 45601.642 | D22: =('Bloomberg Raw Data-5th (2)'!C25+'Bloomberg Raw Data-5th (2)'!D25)/2 -> 0.13000003 | E22: =('Bloomberg Raw Data-5th (2)'!J25+'Bloomberg Raw Data-5th (2)'!K25)/2 -> 7.625 | F22: =D22-E22 -> -7.495 | G22: =G21 -> 101.65 | H22: ='Bloomberg Raw Data-5th (2)'!A25 -> 109 | I22: =2.718281^(-$X$10*$X$11) -> 0.99832373 | J22: =H22*I22 -> 108.81729 | K22: =G22-J22 -> -7.1672864 | L22: =F22-K22 -> -0.32771357 | M22: =D22+J22 -> 108.94729 | N22: =E22+G22 -> 109.275 | O22: =M22-N22 -> -0.32771357 | P22: =IF(M22=N22,"Not Violated","Voilated") -> Voilated | Q22: =M22-G22 -> 7.2972864 | R22: =IF(ABS(E22-Q22)<=0.01,"NO VIOLATION",IF(E22>Q22,"YES", "NO")) -> YES | S22: =IF(ABS(E22-Q22)<=0.01,"NO VIOLATION",IF(E22>Q22,"NO", "YES")) -> NO | AA22: Net Payoff | AC22: =AC12 -> 0.20597993
B23: MRK241115C00110000 | C23: 45601.636 | D23: =('Bloomberg Raw Data-5th (2)'!C26+'Bloomberg Raw Data-5th (2)'!D26)/2 -> 0.10500002 | E23: =('Bloomberg Raw Data-5th (2)'!J26+'Bloomberg Raw Data-5th (2)'!K26)/2 -> 8.5999999 | F23: =D23-E23 -> -8.4949999 | G23: =G22 -> 101.65 | H23: ='Bloomberg Raw Data-5th (2)'!A26 -> 110 | I23: =2.718281^(-$X$10*$X$11) -> 0.99832373 | J23: =H23*I23 -> 109.81561 | K23: =G23-J23 -> -8.1656101 | L23: =F23-K23 -> -0.32938976 | M23: =D23+J23 -> 109.92061 | N23: =E23+G23 -> 110.25 | O23: =M23-N23 -> -0.32938976 | P23: =IF(M23=N23,"Not Violated","Voilated") -> Voilated | Q23: =M23-G23 -> 8.2706101 | R23: =IF(ABS(E23-Q23)<=0.01,"NO VIOLATION",IF(E23>Q23,"YES", "NO")) -> YES | S23: =IF(ABS(E23-Q23)<=0.01,"NO VIOLATION",IF(E23>Q23,"NO", "YES")) -> NO
B24: MRK241115C00111000 | C24: 45600.772 | D24: =('Bloomberg Raw Data-5th (2)'!C27+'Bloomberg Raw Data-5th (2)'!D27)/2 -> 0.075000016 | E24: =('Bloomberg Raw Data-5th (2)'!J27+'Bloomberg Raw Data-5th (2)'!K27)/2 -> 9.2750001 | F24: =D24-E24 -> -9.2000001 | G24: =G23 -> 101.65 | H24: ='Bloomberg Raw Data-5th (2)'!A27 -> 111 | I24: =2.718281^(-$X$10*$X$11) -> 0.99832373 | J24: =H24*I24 -> 110.81393 | K24: =G24-J24 -> -9.1639339 | L24: =F24-K24 -> -0.036066221 | M24: =D24+J24 -> 110.88893 | N24: =E24+G24 -> 110.925 | O24: =M24-N24 -> -0.036066221 | P24: =IF(M24=N24,"Not Violated","Voilated") -> Voilated | Q24: =M24-G24 -> 9.2389339 | R24: =IF(ABS(E24-Q24)<=0.01,"NO VIOLATION",IF(E24>Q24,"YES", "NO")) -> YES | S24: =IF(ABS(E24-Q24)<=0.01,"NO VIOLATION",IF(E24>Q24,"NO", "YES")) -> NO
B25: MRK241115C00112000 | C25: 45600.803 | D25: =('Bloomberg Raw Data-5th (2)'!C28+'Bloomberg Raw Data-5th (2)'!D28)/2 -> 0.13 | E25: =('Bloomberg Raw Data-5th (2)'!J28+'Bloomberg Raw Data-5th (2)'!K28)/2 -> 10.525 | F25: =D25-E25 -> -10.395 | G25: =G24 -> 101.65 | H25: ='Bloomberg Raw Data-5th (2)'!A28 -> 112 | I25: =2.718281^(-$X$10*$X$11) -> 0.99832373 | J25: =H25*I25 -> 111.81226 | K25: =G25-J25 -> -10.162258 | L25: =F25-K25 -> -0.23274251 | M25: =D25+J25 -> 111.94226 | N25: =E25+G25 -> 112.175 | O25: =M25-N25 -> -0.23274251 | P25: =IF(M25=N25,"Not Violated","Voilated") -> Voilated | Q25: =M25-G25 -> 10.292258 | R25: =IF(ABS(E25-Q25)<=0.01,"NO VIOLATION",IF(E25>Q25,"YES", "NO")) -> YES | S25: =IF(ABS(E25-Q25)<=0.01,"NO VIOLATION",IF(E25>Q25,"NO", "YES")) -> NO
B26: MRK241115C00113000 | C26: 45600.657 | D26: =('Bloomberg Raw Data-5th (2)'!C29+'Bloomberg Raw Data-5th (2)'!D29)/2 -> 0.20000002 | E26: =('Bloomberg Raw Data-5th (2)'!J29+'Bloomberg Raw Data-5th (2)'!K29)/2 -> 11.725 | F26: =D26-E26 -> -11.525 | G26: =G25 -> 101.65 | H26: ='Bloomberg Raw Data-5th (2)'!A29 -> 113 | I26: =2.718281^(-$X$10*$X$11) -> 0.99832373 | J26: =H26*I26 -> 112.81058 | K26: =G26-J26 -> -11.160581 | L26: =F26-K26 -> -0.36441857 | M26: =D26+J26 -> 113.01058 | N26: =E26+G26 -> 113.375 | O26: =M26-N26 -> -0.36441857 | P26: =IF(M26=N26,"Not Violated","Voilated") -> Voilated | Q26: =M26-G26 -> 11.360581 | R26: =IF(ABS(E26-Q26)<=0.01,"NO VIOLATION",IF(E26>Q26,"YES", "NO")) -> YES | S26: =IF(ABS(E26-Q26)<=0.01,"NO VIOLATION",IF(E26>Q26,"NO", "YES")) -> NO
B27: MRK241115C00114000 | C27: 45600.708 | D27: =('Bloomberg Raw Data-5th (2)'!C30+'Bloomberg Raw Data-5th (2)'!D30)/2 -> 0.070000002 | E27: =('Bloomberg Raw Data-5th (2)'!J30+'Bloomberg Raw Data-5th (2)'!K30)/2 -> 12.55 | F27: =D27-E27 -> -12.48 | G27: =G26 -> 101.65 | H27: ='Bloomberg Raw Data-5th (2)'!A30 -> 114 | I27: =2.718281^(-$X$10*$X$11) -> 0.99832373 | J27: =H27*I27 -> 113.80891 | K27: =G27-J27 -> -12.158905 | L27: =F27-K27 -> -0.32109467 | M27: =D27+J27 -> 113.87891 | N27: =E27+G27 -> 114.2 | O27: =M27-N27 -> -0.32109467 | P27: =IF(M27=N27,"Not Violated","Voilated") -> Voilated | Q27: =M27-G27 -> 12.228905 | R27: =IF(ABS(E27-Q27)<=0.01,"NO VIOLATION",IF(E27>Q27,"YES", "NO")) -> YES | S27: =IF(ABS(E27-Q27)<=0.01,"NO VIOLATION",IF(E27>Q27,"NO", "YES")) -> NO
B28: MRK241115C00115000 | C28: 45601.64 | D28: =('Bloomberg Raw Data-5th (2)'!C31+'Bloomberg Raw Data-5th (2)'!D31)/2 -> 0.025 | E28: =('Bloomberg Raw Data-5th (2)'!J31+'Bloomberg Raw Data-5th (2)'!K31)/2 -> 13.325 | F28: =D28-E28 -> -13.3 | G28: =G27 -> 101.65 | H28: ='Bloomberg Raw Data-5th (2)'!A31 -> 115 | I28: =2.718281^(-$X$10*$X$11) -> 0.99832373 | J28: =H28*I28 -> 114.80723 | K28: =G28-J28 -> -13.157229 | L28: =F28-K28 -> -0.14277104 | M28: =D28+J28 -> 114.83223 | N28: =E28+G28 -> 114.975 | O28: =M28-N28 -> -0.14277104 | P28: =IF(M28=N28,"Not Violated","Voilated") -> Voilated | Q28: =M28-G28 -> 13.182229 | R28: =IF(ABS(E28-Q28)<=0.01,"NO VIOLATION",IF(E28>Q28,"YES", "NO")) -> YES | S28: =IF(ABS(E28-Q28)<=0.01,"NO VIOLATION",IF(E28>Q28,"NO", "YES")) -> NO
B29: MRK241115C00116000 | C29: 45595.832 | D29: =('Bloomberg Raw Data-5th (2)'!C32+'Bloomberg Raw Data-5th (2)'!D32)/2 -> 0.065000003 | E29: =('Bloomberg Raw Data-5th (2)'!J32+'Bloomberg Raw Data-5th (2)'!K32)/2 -> 14.625 | F29: =D29-E29 -> -14.56 | G29: =G28 -> 101.65 | H29: ='Bloomberg Raw Data-5th (2)'!A32 -> 116 | I29: =2.718281^(-$X$10*$X$11) -> 0.99832373 | J29: =H29*I29 -> 115.80555 | K29: =G29-J29 -> -14.155553 | L29: =F29-K29 -> -0.4044475 | M29: =D29+J29 -> 115.87055 | N29: =E29+G29 -> 116.275 | O29: =M29-N29 -> -0.4044475 | P29: =IF(M29=N29,"Not Violated","Voilated") -> Voilated | Q29: =M29-G29 -> 14.220553 | R29: =IF(ABS(E29-Q29)<=0.01,"NO VIOLATION",IF(E29>Q29,"YES", "NO")) -> YES | S29: =IF(ABS(E29-Q29)<=0.01,"NO VIOLATION",IF(E29>Q29,"NO", "YES")) -> NO
