Workbook

Sheet Income Statement
A1: Company Fundamentals - Income Statement
A2: Company Name | B2: E W Scripps Co (SSP.O)
A3: Country of Exchange | B3: United States of America
A4: Country of Headquarters | B4: United States of America
A5: TRBC Industry Group | B5: Media & Publishing
A6: CF Template | B6: IND
A7: Consolidation Basis | B7: Consolidated
A8: Scaling | B8: Millions
A9: Period | B9: Annual
A10: Export Date | B10: 45835.823
A11: Statement Data | B11: 2024 | C11: 2023 | D11: 2022 | E11: 2021 | F11: 2020 | G11: 2019 | H11: 2018 | I11: 2017 | J11: 2016 | K11: 2015 | L11: 2014 | M11: 2013 | N11: 2012 | O11: 2011 | P11: 2010
A12: Period End Date | B12: 45657 | C12: 45291 | D12: 44926 | E12: 44561 | F12: 44196 | G12: 43830 | H12: 43465 | I12: 43100 | J12: 42735 | K12: 42369 | L12: 42004 | M12: 41639 | N12: 41274 | O12: 40908 | P12: 40543
A13: Statement Date | B13: 45657 | C13: 45291 | D13: 44926 | E13: 44561 | F13: 44196 | G13: 44196 | H13: 44196 | I13: 43465 | J13: 43465 | K13: 43100 | L13: 42369 | M13: 42369 | N13: 42004 | O13: 41274 | P13: 41274
A14: Standardized Currency | B14: USD | C14: USD | D14: USD | E14: USD | F14: USD | G14: USD | H14: USD | I14: USD | J14: USD | K14: USD | L14: USD | M14: USD | N14: USD | O14: USD | P14: USD
A15: Template Type | B15: Industrial - Operating | C15: Industrial - Operating | D15: Industrial - Operating | E15: Industrial - Operating | F15: Industrial - Operating | G15: Industrial - Operating | H15: Industrial - Operating | I15: Industrial - Operating | J15: Industrial - Operating | K15: Industrial - Operating | L15: Industrial - Operating | M15: Industrial - Operating | N15: Industrial - Operating | O15: Industrial - Operating | P15: Industrial - Operating
A17: Income Statement - Standardized (Currency: Standardized)
A18: Field Name | B18: 31-12-2024 | C18: 31-12-2023 | D18: 31-12-2022 | E18: 31-12-2021 | F18: 31-12-2020 | G18: 31-12-2019 | H18: 31-12-2018 | I18: 31-12-2017 | J18: 31-12-2016 | K18: 31-12-2015 | L18: 31-12-2014 | M18: 31-12-2013 | N18: 31-12-2012 | O18: 31-12-2011 | P18: 31-12-2010
A19: Revenues
A20: Revenue from Goods & Services | B20: 2477.29 | C20: 2257.22 | D20: 2417.71 | E20: 2229.71 | F20: 1776.47 | G20: 1274.69 | H20: 1130.23 | I20: 823.59 | J20: 829.47 | K20: 625.82 | L20: 477.73 | M20: 413.24 | N20: 859.71 | O20: 670.87 | P20: 722.69
A21: Sales of Goods & Services - Net - Unclassified | B21: 2477.29 | C21: 2257.22 | D21: 2417.71 | E21: 2229.71 | F21: 1776.47 | G21: 1274.69 | H21: 1130.23 | I21: 823.59 | J21: 829.47 | K21: 625.82 | L21: 477.73 | M21: 413.24 | N21: 859.71 | O21: 670.87 | P21: 722.69
A22: Revenue from Business-Related Activities - Other - Total | B22: 32.49 | C22: 35.7 | D22: 35.51 | E22: 53.83 | F22: 81.01 | G22: 76.71 | H22: 27.13 | I22: 53.38 | J22: 44.98 | K22: 28.36 | L22: 21.02 | M22: 19.12 | N22: 43.75 | O22: 57.79 | P22: 54.2
A23: Revenue from Business Activities - Total | B23: 2509.77 | C23: 2292.91 | D23: 2453.22 | E23: 2283.53 | F23: 1857.48 | G23: 1351.4 | H23: 1157.36 | I23: 876.97 | J23: 874.45 | K23: 654.17 | L23: 498.75 | M23: 432.36 | N23: 903.46 | O23: 728.66 | P23: 776.89
A24: Operating Expenses
A25: Cost of Operating Revenue | B25: 1476 | C25: 1438.43 | D25: 1394.2 | E25: 1268.15 | F25: 637.94 | G25: 482.66 | H25: 375.3 | I25: 284.95 | J25: 227.82 | K25: 161.96 | L25: 87.67 | M25: 84.35 | N25: 207.76 | O25: 200.1 | P25: 200.24
A26: Cost of Revenues - Total | B26: 1476 | C26: 1438.43 | D26: 1394.2 | E26: 1268.15 | F26: 637.94 | G26: 482.66 | H26: 375.3 | I26: 284.95 | J26: 227.82 | K26: 161.96 | L26: 87.67 | M26: 84.35 | N26: 207.76 | O26: 200.1 | P26: 200.24
A27: Cost of Revenues - Unclassified | B27: 1320.77 | C27: 1283.32 | D27: 1233.77 | E27: 1106.23 | F27: 530.79 | G27: 398.31 | H27: 314.59 | I27: 228.61 | J27: 172.62 | K27: 112.17 | L27: 55.49 | M27: 53.83 | N27: 158.43 | O27: 160.03 | P27: 155.35
A28: Amortization in Cost of Revenues | B28: 93.24 | C28: 94.38 | D28: 98.49 | E28: 103.57 | F28: 56.74 | G28: 44.35 | H28: 26.33 | I28: 22.29 | J28: 22.73 | K28: 16.98 | L28: 8.01 | M28: 6.38 | N28: 7.07 | O28: 1.25 | P28: 1.38
A29: Depreciation in Cost of Revenues | B29: 61.99 | C29: 60.73 | D29: 61.94 | E29: 58.36 | F29: 50.42 | G29: 40 | H29: 34.39 | I29: 34.05 | J29: 32.47 | K29: 32.81 | L29: 24.17 | M29: 24.14 | N29: 42.26 | O29: 38.82 | P29: 43.52
A30: Gross Profit - Industrials/Property - Total | B30: 1033.77 | C30: 854.48 | D30: 1059.01 | E30: 1015.38 | F30: 1219.54 | G30: 868.74 | H30: 782.07 | I30: 592.02 | J30: 646.63 | K30: 492.22 | L30: 411.09 | M30: 348.01 | N30: 695.7 | O30: 528.56 | P30: 576.65
A31: Selling, General & Administrative Expenses - Total | B31: 606.18 | C31: 614.77 | D31: 623.16 | E31: 595.11 | F31: 572.28 | G31: 476.97 | H31: 376.44 | I31: 367.74 | J31: 343.57 | K31: 316.42 | L31: 296.03 | M31: 259.48 | N31: 396.24 | O31: 410.86 | P31: 344.65
A32: Selling, General & Administrative Expenses - Unclassified | L32: 31.16 | M32: 26.27 | O32: 51.58
A33: Labor & Related Expenses including Stock-Based Compensation in Selling, General & Administrative Expenses | F33: 572.28 | G33: 476.97 | H33: 376.44 | I33: 367.74 | J33: 343.57 | K33: 316.42 | L33: 257.87 | M33: 225.64 | N33: 396.24 | O33: 348.18 | P33: 344.65
A34: Selling, General & Administrative Expenses - Other - Total | L34: 7 | M34: 7.56 | O34: 11.1
A35: Advertising Expense | L35: 7 | M35: 7.56 | O35: 11.1
A36: Other Operating Expense/(Income) - Net | F36: 324.43 | G36: 276.43 | H36: 233.94 | I36: 185.87 | J36: 173.8 | K36: 149.45 | L36: 82.69 | M36: 88.44 | N36: 209.92 | O36: 119.48 | P36: 186.52
A37: Other Operating Expense | F37: 324.43 | G37: 276.43 | H37: 233.94 | I37: 185.87 | J37: 173.8 | K37: 149.45 | L37: 82.69 | M37: 88.44 | N37: 209.92 | O37: 119.48 | P37: 186.52
A38: Operating Expenses - Total | B38: 2082.18 | C38: 2053.2 | D38: 2017.36 | E38: 1863.25 | F38: 1534.65 | G38: 1236.06 | H38: 985.67 | I38: 838.55 | J38: 745.19 | K38: 627.83 | L38: 466.38 | M38: 432.27 | N38: 813.92 | O38: 730.44 | P38: 731.42
A39: Operating Profit
A40: Operating Profit before Non-Recurring Income/Expense | B40: 427.59 | C40: 239.71 | D40: 435.85 | E40: 420.28 | F40: 322.83 | G40: 115.34 | H40: 171.69 | I40: 38.42 | J40: 129.26 | K40: 26.34 | L40: 32.37 | M40: 0.09 | N40: 89.54 | O40: -1.77 | P40: 45.47
A41: Non-Operating Expenses
...

Sheet Balance Sheet
A1: Company Fundamentals - Balance Sheet
A2: Company Name | B2: E W Scripps Co (SSP.O)
A3: Country of Exchange | B3: United States of America
A4: Country of Headquarters | B4: United States of America
A5: TRBC Industry Group | B5: Media & Publishing
A6: CF Template | B6: IND
A7: Consolidation Basis | B7: Consolidated
A8: Scaling | B8: Millions
A9: Period | B9: Annual
A10: Export Date | B10: 45835.823
A11: Statement Data | B11: 2024 | C11: 2023 | D11: 2022 | E11: 2021 | F11: 2020 | G11: 2019 | H11: 2018 | I11: 2017 | J11: 2016 | K11: 2015 | L11: 2014 | M11: 2013 | N11: 2012 | O11: 2011 | P11: 2010
A12: Period End Date | B12: 45657 | C12: 45291 | D12: 44926 | E12: 44561 | F12: 44196 | G12: 43830 | H12: 43465 | I12: 43100 | J12: 42735 | K12: 42369 | L12: 42004 | M12: 41639 | N12: 41274 | O12: 40908 | P12: 40543
A13: Statement Date | B13: 45657 | C13: 45291 | D13: 44926 | E13: 44561 | F13: 44196 | G13: 44012 | H13: 43465 | I13: 43100 | J13: 43100 | K13: 42369 | L13: 42369 | M13: 41639 | N13: 41364 | O13: 40908 | P13: 40908
A14: Standardized Currency | B14: USD | C14: USD | D14: USD | E14: USD | F14: USD | G14: USD | H14: USD | I14: USD | J14: USD | K14: USD | L14: USD | M14: USD | N14: USD | O14: USD | P14: USD
A15: Template Type | B15: Industrial - Differentiated | C15: Industrial - Differentiated | D15: Industrial - Differentiated | E15: Industrial - Differentiated | F15: Industrial - Differentiated | G15: Industrial - Differentiated | H15: Industrial - Differentiated | I15: Industrial - Differentiated | J15: Industrial - Differentiated | K15: Industrial - Differentiated | L15: Industrial - Differentiated | M15: Industrial - Differentiated | N15: Industrial - Differentiated | O15: Industrial - Differentiated | P15: Industrial - Differentiated
A17: Balance Sheet - Standardized (Currency: Standardized)
A18: Field Name | B18: 31-12-2024 | C18: 31-12-2023 | D18: 31-12-2022 | E18: 31-12-2021 | F18: 31-12-2020 | G18: 31-12-2019 | H18: 31-12-2018 | I18: 31-12-2017 | J18: 31-12-2016 | K18: 31-12-2015 | L18: 31-12-2014 | M18: 31-12-2013 | N18: 31-12-2012 | O18: 31-12-2011 | P18: 31-12-2010
A19: Current Assets
A20: Cash & Short-Term Investments | B20: 23.85 | C20: 35.32 | D20: 18.03 | E20: 66.22 | F20: 576.02 | G20: 32.97 | H20: 102.01 | I20: 148.7 | J20: 134.35 | K20: 108.06 | L20: 158.46 | M20: 221.26 | N20: 242.64 | O20: 127.89 | P20: 204.92
A21: Cash & Cash Equivalents | B21: 23.85 | C21: 35.32 | D21: 18.03 | E21: 66.22 | F21: 576.02 | G21: 32.97 | H21: 102.01 | I21: 148.7 | J21: 134.35 | K21: 108.06 | L21: 158.46 | M21: 221.26 | N21: 242.64 | O21: 127.89 | P21: 204.92
A22: Loans & Receivables - Net - Short-Term | B22: 568.19 | C22: 610.54 | D22: 600.1 | E22: 573.3 | F22: 441.38 | G22: 417.5 | H22: 300.57 | I22: 245.37 | J22: 178.54 | K22: 176.53 | L22: 99.61 | M22: 140.14 | N22: 128.57 | O22: 165.32 | P22: 130.16
A23: Trade Accounts & Trade Notes Receivable - Net | B23: 568.19 | C23: 610.54 | D23: 600.1 | E23: 572.53 | F23: 429.02 | G23: 387.85 | H23: 281.33 | I23: 245.37 | J23: 178.54 | K23: 171.9 | L23: 99.61 | M23: 139.7 | N23: 125.64 | O23: 135.54 | P23: 115.57
A24: Trade Accounts & Trade Notes Receivable - Gross | B24: 575.64 | C24: 615.58 | D24: 605.06 | E24: 576.78 | F24: 432.46 | G24: 391.19 | H24: 285.7 | I24: 247.31 | J24: 180.03 | K24: 173.51 | L24: 101 | M24: 141.73 | N24: 128.13 | O24: 137.42 | P24: 118.36
A25: Provision - Trade Accounts & Trade Notes Receivable | B25: 7.45 | C25: 5.04 | D25: 4.96 | E25: 4.26 | F25: 3.44 | G25: 3.35 | H25: 4.37 | I25: 1.95 | J25: 1.49 | K25: 1.61 | L25: 1.39 | M25: 2.03 | N25: 2.49 | O25: 1.89 | P25: 2.79
A26: Income Tax - Receivables - Short-Term | K26: 4.63 | L26: 0 | M26: 0.44 | N26: 2.93 | O26: 29.79 | P26: 14.6
A27: Receivables - Other - Total | D27: 0 | E27: 0.77 | F27: 12.36 | G27: 29.65 | H27: 19.24
A28: Inventories - Total | M28: 6.54 | N28: 6.44 | O28: 6.78 | P28: 7.86
A29: Assets Held for Sale/Discontinued Operations - Short-Term | F29: 0 | G29: 101.27 | H29: 0 | I29: 136 | J29: 14.22 | K29: 0 | L29: 44.43
A30: Other Current Assets - Total | B30: 37.97 | C30: 30.23 | D30: 25.82 | E30: 62.76 | F30: 1076.78 | G30: 92.19 | H30: 68.43 | I30: 75.47 | J30: 18.79 | K30: 18.04 | L30: 13.33 | M30: 34.12 | N30: 25.06 | O30: 25.42 | P30: 19.63
A31: Deferred Tax - Asset - Short-Term | M31: 17.86 | N31: 7.21 | O31: 7.23 | P31: 8.91
A32: Restricted Accounts - Short-Term | D32: 0 | E32: 34.26 | F32: 1050 | H32: 5.1 | K32: 6.56 | L32: 6.81 | M32: 8.21 | N32: 10.01 | O32: 10.01 | P32: 2.5
A33: Other Current Assets | B33: 37.97 | C33: 30.23 | D33: 25.82 | E33: 28.5 | F33: 26.78 | G33: 92.19 | H33: 63.33 | I33: 75.47 | J33: 18.79 | K33: 11.48 | L33: 6.52 | M33: 8.05 | N33: 7.84 | O33: 8.18 | P33: 8.22
A34: Total Current Assets | B34: 630.02 | C34: 676.09 | D34: 643.94 | E34: 702.28 | F34: 2094.19 | G34: 643.92 | H34: 471.02 | I34: 605.53 | J34: 345.9 | K34: 302.63 | L34: 315.82 | M34: 402.05 | N34: 402.7 | O34: 325.41 | P34: 362.58
A35: Non-Current Assets
A36: Investments - Long-Term | B36: 8.88 | C36: 23.27 | D36: 23.14 | E36: 21.63 | F36: 14.4 | G36: 8.38 | H36: 4.11 | I36: 4.6 | J36: 10.77 | K36: 10.65 | L36: 5.43 | M36: 16.57 | N36: 21.12 | O36: 15.3 | P36: 10.37
A37: Investments - Available for Sale/Held to Maturity - Long-Term | B37: 8.88 | C37: 23.27 | D37: 23.14 | E37: 21.63 | F37: 14.4 | G37: 8.38 | H37: 4.11 | I37: 4.6 | J37: 10.77 | K37: 10.65 | L37: 5.43 | M37: 16.57 | N37: 21.12 | O37: 15.3 | P37: 10.37
A38: Investments in Associates, Joint Ventures and Unconsolidated Subsidiaries | H38: 3.05 | I38: 3.1 | J38: 3.45 | K38: 3.2 | L38: 4.02 | O38: 7.92 | P38: 0.29
A39: Property, Plant & Equipment - Net - Total | B39: 544.04 | C39: 554.45 | D39: 576.47 | E39: 581.77 | F39: 395.39 | G39: 498.57 | H39: 237.93 | I39: 210 | J39: 225.44 | K39: 271.05 | L39: 157.84 | M39: 353.8 | N39: 374.93 | O39: 387.97 | P39: 389.65
A40: Property, Plant & Equipment - excluding Assets Leased Out - Net - Total | B40: 544.04 | C40: 554.45 | D40: 576.47 | E40: 581.77 | F40: 395.39 | G40: 498.57 | H40: 237.93 | I40: 210 | J40: 225.44 | K40: 271.05 | L40: 157.84 | M40: 353.8 | O40: 387.97 | P40: 389.65
A41: Right of Use Tangible Assets - Total - Net | G41: 128.19
...

Sheet Cash Flow
A1: Company Fundamentals - Cash Flow
A2: Company Name | B2: E W Scripps Co (SSP.O)
A3: Country of Exchange | B3: United States of America
A4: Country of Headquarters | B4: United States of America
A5: TRBC Industry Group | B5: Media & Publishing
A6: CF Template | B6: IND
A7: Consolidation Basis | B7: Consolidated
A8: Scaling | B8: Millions
A9: Period | B9: Annual
A10: Export Date | B10: 45835.823
A11: Statement Data | B11: 2024 | C11: 2023 | D11: 2022 | E11: 2021 | F11: 2020 | G11: 2019 | H11: 2018 | I11: 2017 | J11: 2016 | K11: 2015 | L11: 2014 | M11: 2013 | N11: 2012 | O11: 2011 | P11: 2010
A12: Period End Date | B12: 45657 | C12: 45291 | D12: 44926 | E12: 44561 | F12: 44196 | G12: 43830 | H12: 43465 | I12: 43100 | J12: 42735 | K12: 42369 | L12: 42004 | M12: 41639 | N12: 41274 | O12: 40908 | P12: 40543
A13: Statement Date | B13: 45657 | C13: 45291 | D13: 44926 | E13: 44561 | F13: 44196 | G13: 43830 | H13: 43465 | I13: 43100 | J13: 42735 | K13: 42735 | L13: 42735 | M13: 42369 | N13: 41274 | O13: 40908 | P13: 40543
A14: Standardized Currency | B14: USD | C14: USD | D14: USD | E14: USD | F14: USD | G14: USD | H14: USD | I14: USD | J14: USD | K14: USD | L14: USD | M14: USD | N14: USD | O14: USD | P14: USD
A15: Template Type | B15: Industrial - Indirect | C15: Industrial - Indirect | D15: Industrial - Indirect | E15: Industrial - Indirect | F15: Industrial - Indirect | G15: Industrial - Indirect | H15: Industrial - Indirect | I15: Industrial - Indirect | J15: Industrial - Indirect | K15: Industrial - Indirect | L15: Industrial - Indirect | M15: Industrial - Indirect | N15: Industrial - Indirect | O15: Industrial - Indirect | P15: Industrial - Indirect
A17: Cash Flow - Standardized (Currency: Standardized)
A18: Field Name | B18: 31-12-2024 | C18: 31-12-2023 | D18: 31-12-2022 | E18: 31-12-2021 | F18: 31-12-2020 | G18: 31-12-2019 | H18: 31-12-2018 | I18: 31-12-2017 | J18: 31-12-2016 | K18: 31-12-2015 | L18: 31-12-2014 | M18: 31-12-2013 | N18: 31-12-2012 | O18: 31-12-2011 | P18: 31-12-2010
A19: Operating Cash Flow - Indirect
A20: Profit/(Loss) - Starting Line - Cash Flow | B20: 146.22 | C20: -947.78 | D20: 195.9 | E20: 122.71 | F20: 269.33 | G20: -18.38 | H20: 19.75 | I20: -14.62 | J20: 67.24 | K20: -82.48 | L20: 10.53 | M20: -0.47 | N20: 39.92 | O20: -15.69 | P20: 130.41
A21: Non-cash Items & Reconciliation Adjustments - Cash Flow | B21: 163.81 | C21: 1096.17 | D21: 178.47 | E21: 171.68 | F21: 68.87 | G21: 90.47 | H21: 139.43 | I21: 65.31 | J21: 115.12 | K21: 135.1 | L21: 38.52 | M21: 38.45 | N21: 66.16 | O21: 67.41 | P21: -34.05
A22: Discontinued Operations - Gain/(Loss) - Net of Tax - Cash Flow - to Reconcile | E22: -6.81 | F22: -115.77 | H22: 36.33 | I22: 2.6 | K22: 15.84 | L22: -1.07 | M22: -9.61 | P22: -94.84
A23: Equity Income/(Loss) in Net Earnings - Cash Flow - to Reconcile | B23: -19.89
A24: Other Non-Cash Items & Reconciliation Adjustments - Cash Flow - to Reconcile | B24: 29.06 | C24: 24.79 | D24: -20.21 | E24: -6.18 | F24: -21.68 | G24: -4.14 | H24: 7.51 | I24: -23.21 | J24: 5.61 | K24: 58.91 | L24: -2.09 | M24: 12.8 | N24: -0.16 | O24: 10.49 | P24: -17.75
A25: Depreciation, Depletion & Amortization including Impairment - Cash Flow - to Reconcile | B25: 155.23 | C25: 1107.11 | D25: 160.43 | E25: 161.92 | F25: 107.16 | G25: 86.99 | H25: 63.99 | I25: 92.08 | J25: 58.58 | K25: 76.57 | L25: 32.18 | M25: 30.52 | N25: 49.33 | O25: 40.07 | P25: 44.89
A26: Depreciation & Depletion - Property, Plant & Equipment - Cash Flow - to Reconcile | B26: 155.23 | C26: 155.1 | D26: 160.43 | E26: 161.92 | F26: 107.16 | G26: 86.99 | H26: 63.99 | I26: 56.34 | J26: 58.58 | K26: 51.95 | L26: 32.18 | M26: 30.52 | N26: 49.33 | O26: 40.07 | P26: 44.89
A27: Impairment - Property, Plant & Equipment including Intangible Assets - Cash Flow - to Reconcile | C27: 952 | I27: 35.73 | K27: 24.61
A28: Deferred Income Taxes & Income Tax Credits - Cash Flow - to Reconcile | B28: -0.15 | C28: -63.7 | D28: 12.92 | E28: 9.73 | F28: 80.64 | G28: -4.66 | H28: 19.35 | I28: -16.08 | J28: 39.27 | K28: -26.83 | L28: 5.38 | M28: -4.34 | N28: 8.3 | O28: 9.79 | P28: 25.82
A29: Assets Sale - Gain/(Loss) - Cash Flow - to Reconcile | B29: -18.42 | C29: 2.34 | D29: 5.87 | E29: -112.06 | F29: 0.66 | G29: -2.62 | H29: 1.51 | I29: -5.94 | J29: 0.54 | K29: 0.48 | L29: -2.87 | M29: 3.3 | N29: 0.47 | O29: -0.12 | P29: -1.06
A30: Financial Assets - Unrealized Gain/(Loss) - Cash Flow - to Reconcile | E30: 99.12
A31: Share Based Payments - Cash Flow - to Reconcile | B31: 17.99 | C31: 25.63 | D31: 19.46 | E31: 25.96 | F31: 17.86 | G31: 14.91 | H31: 10.74 | I31: 15.87 | J31: 11.13 | K31: 10.13 | L31: 6.99 | M31: 5.78 | N31: 8.22 | O31: 7.2 | P31: 8.89
A32: Cash Flow from Operating Activities before Changes in Working Capital | B32: 310.03 | C32: 148.38 | D32: 374.37 | E32: 294.39 | F32: 338.2 | G32: 72.09 | H32: 159.18 | I32: 50.69 | J32: 182.36 | K32: 52.62 | L32: 49.05 | M32: 37.97 | N32: 106.09 | O32: 51.73 | P32: 96.36
A33: Working Capital - Increase/(Decrease) - Cash Flow | B33: 55.65 | C33: -36.78 | D33: -62.94 | E33: -63.45 | F33: 17.13 | G33: -99.55 | H33: -28.95 | I33: -20.51 | J33: -35.86 | K33: -43.79 | L33: 29.24 | M33: -31.21 | N33: 66.5 | O33: -36.94 | P33: -30.39
A34: Accounts Receivables - Decrease/(Increase) - Cash Flow | B34: 42.35 | C34: -10.44 | D34: -26.87 | E34: -31.62 | F34: -40.52 | G34: -104.96 | H34: -22.13 | I34: -22.52 | N34: 44.59 | O34: -25.58 | P34: -5.26
A35: Inventories - Decrease/(Increase) - Cash Flow | N35: 0.35 | O35: 1.08 | P35: -0.87
A36: Prepaid Expenses - Decrease/(Increase) - Cash Flow | N36: 5.9 | O36: 4.84 | P36: -62.77
A37: Other Assets - Decrease/(Increase) - Cash Flow | B37: -7.74 | C37: -4.63 | D37: 5.65 | E37: 12.49 | F37: 22.64 | G37: -11.35 | H37: -6.21
A38: Accounts Payable - Increase/(Decrease) - Cash Flow | B38: 13.18 | C38: -3.54 | D38: 7.31 | E38: 18.53 | F38: 19.52 | G38: 1.57 | H38: 0.97 | I38: -7.26 | N38: 5.63 | O38: -16.74 | P38: 12.07
A39: Accrued Expenses - Increase/(Decrease) - Cash Flow | B39: 10.01 | C39: 3.16 | D39: -22.97 | E39: 24.87 | F39: 7.16 | G39: 17.09 | H39: 7.69 | I39: 15.82 | N39: 2.72 | O39: -10.04 | P39: 8.43
A40: Other Liabilities - Increase/(Decrease) -Total - Cash Flow | B40: 3.3 | C40: -6 | D40: -3.11 | E40: -7.08 | F40: 3.4 | G40: 0.22 | H40: 2.92
A41: Other Assets & Liabilities - Increase/(Decrease) - Net - Cash Flow | B41: -5.44 | C41: -15.33 | D41: -22.94 | E41: -80.64 | F41: 4.93 | G41: -2.12 | H41: -12.18 | I41: -6.55 | J41: -35.86 | K41: -43.79 | L41: 29.24 | M41: -31.21 | N41: 7.3 | O41: 9.52 | P41: 18.02
...

Sheet Operating Metrics
A1: Company Fundamentals - Operating Metrics
A2: Company Name | B2: E W Scripps Co (SSP.O)
A3: Country of Exchange | B3: United States of America
A4: Country of Headquarters | B4: United States of America
A5: TRBC Industry Group | B5: Media & Publishing
A6: CF Template | B6: IND
A7: Consolidation Basis | B7: Consolidated
A8: Scaling | B8: Millions
A9: Period | B9: Annual
A10: Measure system | B10: Metric
A11: Statement Data | B11: 2024 | C11: 2023 | D11: 2022 | E11: 2021 | F11: 2020 | G11: 2019 | H11: 2018 | I11: 2017 | J11: 2016
A12: Period End Date | B12: 45657 | C12: 45291 | D12: 44926 | E12: 44561 | F12: 44196 | G12: 43830 | H12: 43465 | I12: 43100 | J12: 42735
A13: Statement Date | B13: 45657 | C13: 45291 | D13: 44926 | E13: 44561 | F13: 44196 | G13: 44196 | H13: 43465 | I13: 43465 | J13: 43100
A14: Standardized Currency | B14: USD | C14: USD | D14: USD | E14: USD | F14: USD | G14: USD | H14: USD | I14: USD | J14: USD
A15: Template Type | B15: Industrial | C15: Industrial | D15: Industrial | E15: Industrial | F15: Industrial | G15: Industrial | H15: Industrial | I15: Industrial | J15: Industrial
A17: Operating Metrics - Standardized (Currency: Standardized)
A18: Field Name | B18: 31-12-2024 | C18: 31-12-2023 | D18: 31-12-2022 | E18: 31-12-2021 | F18: 31-12-2020 | G18: 31-12-2019 | H18: 31-12-2018 | I18: 31-12-2017 | J18: 31-12-2016
A19: Revenues, Costs & Other Measures
A20: Advertisement Revenue - Total | B20: 552253000 | C20: 598824000 | D20: 1549277000 | E20: 1592121000 | F20: 915515000 | G20: 861386000 | H20: 836049000 | I20: 563879000 | J20: 609612000
A21: Users & Payers
A22: Number of Subscribers - Media - Total | F22: 35000000

Sheet Financial Summary
A1: Company Fundamentals - Financial Summary
A2: Company Name | B2: E W Scripps Co (SSP.O)
A3: Country of Exchange | B3: United States of America
A4: Country of Headquarters | B4: United States of America
A5: TRBC Industry Group | B5: Media & Publishing
A6: CF Template | B6: IND
A7: Consolidation Basis | B7: Consolidated
A8: Scaling | B8: Millions
A9: Period | B9: Annual
A10: Export Date | B10: 45835.823
A11: Statement Data | B11: 2024 | C11: 2023 | D11: 2022 | E11: 2021 | F11: 2020 | G11: 2019 | H11: 2018 | I11: 2017 | J11: 2016 | K11: 2015 | L11: 2014 | M11: 2013 | N11: 2012 | O11: 2011 | P11: 2010
A12: Period End Date | B12: 45657 | C12: 45291 | D12: 44926 | E12: 44561 | F12: 44196 | G12: 43830 | H12: 43465 | I12: 43100 | J12: 42735 | K12: 42369 | L12: 42004 | M12: 41639 | N12: 41274 | O12: 40908 | P12: 40543
A13: Statement Date | B13: 45657 | C13: 45291 | D13: 44926 | E13: 44561 | F13: 44196 | G13: 44196 | H13: 44196 | I13: 43465 | J13: 43465 | K13: 43100 | L13: 42369 | M13: 42369 | N13: 42004 | O13: 41274 | P13: 41274
A14: Standardized Currency | B14: USD | C14: USD | D14: USD | E14: USD | F14: USD | G14: USD | H14: USD | I14: USD | J14: USD | K14: USD | L14: USD | M14: USD | N14: USD | O14: USD | P14: USD
A15: Template Type | B15: Industrial - Operating | C15: Industrial - Operating | D15: Industrial - Operating | E15: Industrial - Operating | F15: Industrial - Operating | G15: Industrial - Operating | H15: Industrial - Operating | I15: Industrial - Operating | J15: Industrial - Operating | K15: Industrial - Operating | L15: Industrial - Operating | M15: Industrial - Operating | N15: Industrial - Operating | O15: Industrial - Operating | P15: Industrial - Operating
A17: Financial Summary - Standardized (Currency: Standardized)
A18: Field Name | B18: 31-12-2024 | C18: 31-12-2023 | D18: 31-12-2022 | E18: 31-12-2021 | F18: 31-12-2020 | G18: 31-12-2019 | H18: 31-12-2018 | I18: 31-12-2017 | J18: 31-12-2016 | K18: 31-12-2015 | L18: 31-12-2014 | M18: 31-12-2013 | N18: 31-12-2012 | O18: 31-12-2011 | P18: 31-12-2010
A19: Selected Income Statement Items
A20: Revenue from Business Activities - Total | B20: 2509.77 | C20: 2292.91 | D20: 2453.22 | E20: 2283.53 | F20: 1857.48 | G20: 1351.4 | H20: 1157.36 | I20: 876.97 | J20: 874.45 | K20: 654.17 | L20: 498.75 | M20: 432.36 | N20: 903.46 | O20: 728.66 | P20: 776.89
A21: Gross Profit - Industrials/Property - Total | B21: 1033.77 | C21: 854.48 | D21: 1059.01 | E21: 1015.38 | F21: 1219.54 | G21: 868.74 | H21: 782.07 | I21: 592.02 | J21: 646.63 | K21: 492.22 | L21: 411.09 | M21: 348.01 | N21: 695.7 | O21: 528.56 | P21: 576.65
A22: Operating Profit before Non-Recurring Income/Expense | B22: 427.59 | C22: 239.71 | D22: 435.85 | E22: 420.28 | F22: 322.83 | G22: 115.34 | H22: 171.69 | I22: 38.42 | J22: 129.26 | K22: 26.34 | L22: 32.37 | M22: 0.09 | N22: 89.54 | O22: -1.77 | P22: 45.47
A23: Earnings before Interest, Taxes, Depreciation & Amortization (EBITDA) | B23: 582.82 | C23: 394.82 | D23: 596.29 | E23: 582.2 | F23: 429.98 | G23: 202.33 | H23: 235.68 | I23: 94.76 | J23: 187.84 | K23: 78.3 | L23: 64.55 | M23: 30.61 | N23: 138.87 | O23: 38.29 | P23: 90.37
A24: Income before Discontinued Operations & Extraordinary Items | B24: 146.22 | C24: -947.78 | D24: 195.9 | E24: 115.9 | F24: 153.56 | G24: -1.91 | H24: 69.89 | I24: -16.22 | J24: 59.92 | K24: -73.87 | L24: 9.46 | M24: -10.09 | N24: 39.92 | O24: -15.69 | P24: 28.87
A25: Selected Balance Sheet Items
A26: Cash & Cash Equivalents | B26: 23.85 | C26: 35.32 | D26: 18.03 | E26: 66.22 | F26: 576.02 | G26: 32.97 | H26: 102.01 | I26: 148.7 | J26: 134.35 | K26: 108.06 | L26: 158.46 | M26: 221.26 | N26: 242.64 | O26: 127.89 | P26: 204.92
A27: Cash & Short-Term Investments | B27: 23.85 | C27: 35.32 | D27: 18.03 | E27: 66.22 | F27: 576.02 | G27: 32.97 | H27: 102.01 | I27: 148.7 | J27: 134.35 | K27: 108.06 | L27: 158.46 | M27: 221.26 | N27: 242.64 | O27: 127.89 | P27: 204.92
A28: Total Assets | B28: 5198.58 | C28: 5410.12 | D28: 6431.01 | E28: 6658.31 | F28: 4859.39 | G28: 3561.86 | H28: 2130.06 | I28: 2129.55 | J28: 1735.91 | K28: 1680.86 | L28: 1031.1 | M28: 966.13 | N28: 1030.77 | O28: 970.53 | P28: 827.54
A29: Debt - Total | B29: 2607.19 | C29: 2942.58 | D29: 2900.89 | E29: 3148.01 | F29: 2933.97 | G29: 1915.03 | H29: 688.76 | I29: 693.28 | J29: 393.19 | K29: 399.14 | L29: 196.37 | M29: 200 | N29: 196.1 | O29: 212 | P29: 0
A30: Common Equity - Total | B30: 901.16 | C30: 741.63 | D30: 1718.58 | E30: 1560.5 | F30: 1163.27 | G30: 897.94 | H30: 926.17 | I30: 936.85 | J30: 945.94 | K30: 900.98 | L30: 518.28 | M30: 545.77 | N30: 537.7 | O30: 514.52 | P30: 588.9
A31: Selected Cash Flow Items
A32: Net Cash Flow from Operating Activities | B32: 365.68 | C32: 111.6 | D32: 311.42 | E32: 230.94 | F32: 355.33 | G32: -27.45 | H32: 130.23 | I32: 30.19 | J32: 146.49 | K32: 8.83 | L32: 78.3 | M32: 6.76 | N32: 172.58 | O32: 14.79 | P32: 65.97
A33: Depreciation, Depletion & Amortization including Impairment - Cash Flow - to Reconcile | B33: 155.23 | C33: 1107.11 | D33: 160.43 | E33: 161.92 | F33: 107.16 | G33: 86.99 | H33: 63.99 | I33: 92.08 | J33: 58.58 | K33: 76.57 | L33: 32.18 | M33: 30.52 | N33: 49.33 | O33: 40.07 | P33: 44.89
A34: Capital Expenditures - Net - Cash Flow | B34: 44.79 | C34: 59.63 | D34: 43.12 | E34: 41.11 | F34: 18.47 | G34: 78.95 | H34: 58.95 | I34: 27.68 | J34: 27.89 | K34: 6.88 | L34: 10.44 | M34: 15.82 | N34: 30.21 | O34: 226.59 | P34: 18.33
A35: Net Change in Cash - Total | B35: -11.47 | C35: 17.29 | D35: -82.45 | E35: -1525.54 | F35: 1593.05 | G35: -74.15 | H35: -41.58 | I35: 14.35 | J35: 19.73 | K35: -50.65 | L35: -64.2 | M35: -21.39 | N35: 114.75 | O35: -77.03 | P35: 197.24
A36: Free Cash Flow Net of Dividends | B36: 300.42 | C36: 3.98 | D36: 217.63 | E36: 124.7 | F36: 291.92 | G36: -129.73 | H36: 53.35 | I36: 2.51 | J36: 118.55 | K36: -73.8 | L36: 62 | M36: -9.1 | N36: 142.37 | O36: -213.54 | P36: 46.88
A37: Selected Per Share Data
A38: Dividend Yield - Common Stock - Gross - Issue Specific - % | B38: 0 | C38: 0 | D38: 0 | E38: 0 | F38: 1.31 | G38: 1.27 | H38: 1.27 | I38: 0 | J38: 0 | K38: 0 | L38: 0 | M38: 0 | N38: 0 | O38: 0 | P38: 0
A39: Dividend Yield - Common Stock - Net - Issue Specific - % | B39: 0 | C39: 0 | D39: 0 | E39: 0 | F39: 1.31 | G39: 1.27 | H39: 1.27 | I39: 0 | J39: 0 | K39: 0 | L39: 0 | M39: 0 | N39: 0 | O39: 0 | P39: 0
A40: EPS - Diluted - excluding Extraordinary Items Applicable to Common - Total | B40: 1.02 | C40: -11.84 | D40: 1.62 | E40: 1.39 | F40: 1.83 | G40: -0.02 | H40: 0.85 | I40: -0.18 | J40: 0.71 | K40: -0.95 | L40: 0.17 | M40: -0.18 | N40: 0.73 | O40: -0.27 | P40: 0.25
A41: Shares used to calculate Diluted EPS - Total | B41: 86.07 | C41: 84.27 | D41: 87.35 | E41: 87.98 | F41: 81.83 | G41: 80.83 | H41: 81.93 | I41: 82.05 | J41: 83.64 | K41: 77.37 | L41: 57.24 | M41: 56.52 | N41: 55.38 | O41: 57.22 | P41: 57
...

Sheet Analysis
A1: Year | B1: 2014 | C1: 2015 | D1: 2016 | E1: 2017
A2: Revenue | B2: ='Income Statement'!L23 -> 498.75 | C2: ='Income Statement'!K23 -> 654.17 | D2: ='Income Statement'!J23 -> 874.45 | E2: ='Income Statement'!I23 -> 876.97
A3: CAGR(2014-2017) | B3: =(E2/B2)^(1/3)-1 -> 0.20698149
A4: Assumed Growth Rate | B4: 0.08 | F4: Although Scripps grew at a 21% CAGR from 2014 to 2017, structural industry changes such as cord-cutting, digital disruption, and advertising migration led analysts to project low-to-mid single-digit growth for traditional networks. (PwC Global E&M Outlook 2017–2021; Scripps 10-K 2016). Therefore, we apply a conservative but fair 8% annual revenue growth in our forecast.
A5: WACC | B5: =B89 -> 0.064350633 | F5: Aswath Damodaran – NYU Stern 2023 WACC Estimates
A6: g | B6: 0.025 | F6: ValueInvesting.io – Discovery WACC Breakdown
A7: Rf | B7: 0.0425 | F7: 10 Year Treasury
A8: Rm-Rf | B8: 0.055 | F8: Damodaran (NYU Stern Professor) publishes annual estimates, For U.S. in 2024/2025: ~5.5% Source: NYU Stern ERPs
A9: Beta | B9: 0.74 | F9: The beta of 0.74 used in this analysis is consistent with publicly available data from Reuters, representing the stock’s historical volatility relative to the market prior to its acquisition by Discovery.
A10: Rd | B10: ='Income Statement'!I177/Analysis!B51 -> 0.038512578
A11: Tc | B11: 0.25
A14: DCF Analysis
A16: Year | B16: 2014 | C16: 2015 | D16: 2016 | E16: 2017 | F16: 2018E | G16: 2019E | H16: 2020E | I16: 2021E | J16: 2022E | K16: 2023E | L16: 2024E | M16: 2025E
A17: Revenue | B17: =B2 -> 498.75 | C17: =C2 -> 654.17 | D17: =D2 -> 874.45 | E17: =E2 -> 876.97 | F17: =E17*(1+$B$4) -> 947.1276 | G17: =F17*(1+$B$4) -> 1022.8978 | H17: =G17*(1+$B$4) -> 1104.7296 | I17: =H17*(1+$B$4) -> 1193.108 | J17: =I17*(1+$B$4) -> 1288.5566 | K17: =J17*(1+$B$4) -> 1391.6412 | L17: =K17*(1+$B$4) -> 1502.9725 | M17: =L17*(1+$B$4) -> 1623.2103
A18: =A3 -> CAGR(2014-2017) | E18: =B3 -> 0.20698149
A19: =A4 -> Assumed Growth Rate | E19: =B4 -> 0.08
A21: Cost of Revenue | B21: ='Income Statement'!L26 -> 87.67 | C21: ='Income Statement'!K26 -> 161.96 | D21: ='Income Statement'!J26 -> 227.82 | E21: ='Income Statement'!I26 -> 284.95 | F21: =E17*$E$22 -> 284.95 | G21: =F17*$E$22 -> 307.746 | H21: =G17*$E$22 -> 332.36568 | I21: =H17*$E$22 -> 358.95493 | J21: =I17*$E$22 -> 387.67133 | K21: =J17*$E$22 -> 418.68504 | L21: =K17*$E$22 -> 452.17984 | M21: =L17*$E$22 -> 488.35423
A22: CoR % of Revenue | E22: =E21/E17 -> 0.3249256
A24: Other Op Exp | B24: ='Income Statement'!L36 -> 82.69 | C24: ='Income Statement'!K36 -> 149.45 | D24: ='Income Statement'!J36 -> 173.8 | E24: ='Income Statement'!I36 -> 185.87 | F24: =E17*$E$25 -> 185.87 | G24: =F17*$E$25 -> 200.7396 | H24: =G17*$E$25 -> 216.79877 | I24: =H17*$E$25 -> 234.14267 | J24: =I17*$E$25 -> 252.87408 | K24: =J17*$E$25 -> 273.10401 | L24: =K17*$E$25 -> 294.95233 | M24: =L17*$E$25 -> 318.54852
A25: Op Exp % of Revenue | E25: =E24/E17 -> 0.21194568
A27: EBIT | F27: =F17-F21-F24 -> 476.3076 | G27: =G17-G21-G24 -> 514.41221 | H27: =H17-H21-H24 -> 555.56518 | I27: =I17-I21-I24 -> 600.0104 | J27: =J17-J21-J24 -> 648.01123 | K27: =K17-K21-K24 -> 699.85213 | L27: =L17-L21-L24 -> 755.8403 | M27: =M17-M21-M24 -> 816.30752
A28: EBIT Margin % | F28: =F27/F17 -> 0.50289697 | G28: =G27/G17 -> 0.50289697 | H28: =H27/H17 -> 0.50289697 | I28: =I27/I17 -> 0.50289697 | J28: =J27/J17 -> 0.50289697 | K28: =K27/K17 -> 0.50289697 | L28: =L27/L17 -> 0.50289697 | M28: =M27/M17 -> 0.50289697
A30: Depreciation and Ammortization | B30: ='Cash Flow'!L98 -> 32.18 | C30: ='Cash Flow'!K98 -> 51.95 | D30: ='Cash Flow'!J98 -> 58.58 | E30: ='Cash Flow'!I98 -> 56.34 | F30: =F17*$E$31 -> 60.8472 | G30: =G17*$E$31 -> 65.714976 | H30: =H17*$E$31 -> 70.972174 | I30: =I17*$E$31 -> 76.649948 | J30: =J17*$E$31 -> 82.781944 | K30: =K17*$E$31 -> 89.404499 | L30: =L17*$E$31 -> 96.556859 | M30: =M17*$E$31 -> 104.28141
A31: D&A % of Revenue | E31: =E30/E17 -> 0.064243931
A33: CapEx | B33: ='Financial Summary'!L34 -> 10.44 | C33: ='Financial Summary'!K34 -> 6.88 | D33: ='Financial Summary'!J34 -> 27.89 | E33: ='Financial Summary'!I34 -> 27.68 | F33: =E17*$E$34 -> 27.68 | G33: =F17*$E$34 -> 29.8944 | H33: =G17*$E$34 -> 32.285952 | I33: =H17*$E$34 -> 34.868828 | J33: =I17*$E$34 -> 37.658334 | K33: =J17*$E$34 -> 40.671001 | L33: =K17*$E$34 -> 43.924681 | M33: =L17*$E$34 -> 47.438656
A34: Capex % of Revenue | E34: =E33/E17 -> 0.031563223
A37: NWC | B37: =('Balance Sheet'!L22+'Balance Sheet'!L23+'Balance Sheet'!L27+'Balance Sheet'!L28+'Balance Sheet'!L33)-('Balance Sheet'!L77+'Balance Sheet'!L89+'Balance Sheet'!L90) -> 120.84 | C37: =('Balance Sheet'!K22+'Balance Sheet'!K23+'Balance Sheet'!K27+'Balance Sheet'!K28+'Balance Sheet'!K33)-('Balance Sheet'!K77+'Balance Sheet'!K89+'Balance Sheet'!K90) -> 246.74 | D37: =('Balance Sheet'!J22+'Balance Sheet'!J23+'Balance Sheet'!J27+'Balance Sheet'!J28+'Balance Sheet'!J33)-('Balance Sheet'!J77+'Balance Sheet'!J89+'Balance Sheet'!J90) -> 281.19 | E37: =('Balance Sheet'!I22+'Balance Sheet'!I23+'Balance Sheet'!I27+'Balance Sheet'!I28+'Balance Sheet'!I33)-('Balance Sheet'!I77+'Balance Sheet'!I89+'Balance Sheet'!I90) -> 380.62
A38: ΔNWC | C38: =C37-B37 -> 125.9 | D38: =D37-C37 -> 34.45 | E38: =E37-D37 -> 99.43 | F38: =E17*$E$40 -> 100.91961 | G38: =F17*$E$40 -> 108.99318 | H38: =G17*$E$40 -> 117.71264 | I38: =H17*$E$40 -> 127.12965 | J38: =I17*$E$40 -> 137.30002 | K38: =J17*$E$40 -> 148.28402 | L38: =K17*$E$40 -> 160.14674 | M38: =L17*$E$40 -> 172.95848
A39: ΔNWC % of Revenue | C39: =C38/C17 -> 0.19245762 | D39: =D38/D17 -> 0.039396192 | E39: =E38/E17 -> 0.11337902
A40: Avg ΔNWC as % of Revenue | E40: =AVERAGE(C39:E39) -> 0.11507761
N42: Terminal Value | O42: PV of Terminal Value
A43: FCFF | F43: =F27*(1-$E$63)+F30-F33-F38 -> 289.47829 | G43: =G27*(1-$E$63)+G30-G33-G38 -> 312.63655 | H43: =H27*(1-$E$63)+H30-H33-H38 -> 337.64748 | I43: =I27*(1-$E$63)+I30-I33-I38 -> 364.65927 | J43: =J27*(1-$E$63)+J30-J33-J38 -> 393.83202 | K43: =K27*(1-$E$63)+K30-K33-K38 -> 425.33858 | L43: =L27*(1-$E$63)+L30-L33-L38 -> 459.36566 | M43: =M27*(1-$E$63)+M30-M33-M38 -> 496.11492 | N43: =M43*(1+$B$6)/($B$5-$B$6) -> 12922.734 | O43: =N43*M45 -> 7846.5119
A45: Discount Factor | F45: =1/(1+$B$5)^1 -> 0.93954001 | G45: =1/(1+$B$5)^2 -> 0.88273542 | H45: =1/(1+$B$5)^3 -> 0.82936524 | I45: =1/(1+$B$5)^4 -> 0.77922183 | J45: =1/(1+$B$5)^5 -> 0.73211008 | K45: =1/(1+$B$5)^6 -> 0.68784671 | L45: =1/(1+$B$5)^7 -> 0.6462595 | M45: =1/(1+$B$5)^8 -> 0.60718665
N46: Enterprise Value
A47: PV of FCFF | F47: =F43*F45 -> 271.97643 | G47: =G43*G45 -> 275.97536 | H47: =H43*H45 -> 280.03308 | I47: =I43*I45 -> 284.15046 | J47: =J43*J45 -> 288.32839 | K47: =K43*K45 -> 292.56774 | L47: =L43*L45 -> 296.86942 | M47: =M43*M45 -> 301.23435 | N47: =SUM(F47:M47) -> 2291.1352
A50: Year | B50: 2017
A51: Total Debt | B51: ='Financial Summary'!I29 -> 693.28
A52: Cash & Cash Equivalents | B52: ='Financial Summary'!I26 -> 148.7
A53: Net Debt | B53: =B51-B52 -> 544.58
A54: Equity Value | B54: =N47-B53 -> 1746.5552
...

Sheet FCFF
B1: 2018E | C1: 2019E | D1: 2020E | E1: 2021E | F1: 2022E | G1: 2023E | H1: 2024E | I1: 2025E
A2: Free Cash Flow To The Firm (FCFF)
A3: EBIT*(1-Tax Rate) | B3: =Analysis!F27*(1-Analysis!$E$63) -> 357.2307 | C3: =Analysis!G27*(1-Analysis!$E$63) -> 385.80916 | D3: =Analysis!H27*(1-Analysis!$E$63) -> 416.67389 | E3: =Analysis!I27*(1-Analysis!$E$63) -> 450.0078 | F3: =Analysis!J27*(1-Analysis!$E$63) -> 486.00842 | G3: =Analysis!K27*(1-Analysis!$E$63) -> 524.8891 | H3: =Analysis!L27*(1-Analysis!$E$63) -> 566.88023 | I3: =Analysis!M27*(1-Analysis!$E$63) -> 612.23064
A4: [+] Depreciation | B4: =Analysis!F30 -> 60.8472 | C4: =Analysis!G30 -> 65.714976 | D4: =Analysis!H30 -> 70.972174 | E4: =Analysis!I30 -> 76.649948 | F4: =Analysis!J30 -> 82.781944 | G4: =Analysis!K30 -> 89.404499 | H4: =Analysis!L30 -> 96.556859 | I4: =Analysis!M30 -> 104.28141
A5: [-] Changes in Working Capital | B5: =Analysis!F38 -> 100.91961 | C5: =Analysis!G38 -> 108.99318 | D5: =Analysis!H38 -> 117.71264 | E5: =Analysis!I38 -> 127.12965 | F5: =Analysis!J38 -> 137.30002 | G5: =Analysis!K38 -> 148.28402 | H5: =Analysis!L38 -> 160.14674 | I5: =Analysis!M38 -> 172.95848
A6: [-] Capex | B6: =Analysis!F33 -> 27.68 | C6: =Analysis!G33 -> 29.8944 | D6: =Analysis!H33 -> 32.285952 | E6: =Analysis!I33 -> 34.868828 | F6: =Analysis!J33 -> 37.658334 | G6: =Analysis!K33 -> 40.671001 | H6: =Analysis!L33 -> 43.924681 | I6: =Analysis!M33 -> 47.438656
A7: Free Cashflow to the Firm (FCFF) | B7: =B3+B4-B5-B6 -> 289.47829 | C7: =C3+C4-C5-C6 -> 312.63655 | D7: =D3+D4-D5-D6 -> 337.64748 | E7: =E3+E4-E5-E6 -> 364.65927 | F7: =F3+F4-F5-F6 -> 393.83202 | G7: =G3+G4-G5-G6 -> 425.33858 | H7: =H3+H4-H5-H6 -> 459.36566 | I7: =I3+I4-I5-I6 -> 496.11492
